Workbook
Name A: #REF!
Name bzfz: '[1]披露表(标准)'!$D$6:$D$29
Name bzfz: '[2]披露表(标准)'!$D$6:$D$29
Name didi: #REF!
Name dxn: [3]dxnsjtempsheet!$A:$G
Name fzxm: '[4]披露表(标准)'!$D$6:$D$42
Name fzxm: #REF!
Name gzfzfl: '[5]披露表(国资)'!$D$5:$D$10
Name gzfzxm: '[1]披露表(国资)'!$D$14:$D$54
Name gzfzxm: '[6]披露表(国资)'!$D$6:$D$15
Name gzfzxm2: '[7]披露表(国资)'!$D$43:$D$50
Name hkd: 1.0611
Name NvsASD: "V2001-12-31"
Name NvsAutoDrillOk: "VN"
Name NvsElapsedTime: 0.000181828705535736
Name NvsEndTime: 37274.7274061343
Name NvsInstSpec: "%"
Name NvsLayoutType: "M3"
Name NvsPanelEffdt: "V1900-01-01"
Name NvsPanelSetid: "VFCMNY"
Name NvsReqBU: "VFCMHK"
Name NvsReqBUOnly: "VY"
Name NvsTransLed: "VN"
Name NvsTreeASD: "V2001-12-31"
Name NvsValTbl.ACCOUNT: "GL_ACCOUNT_TBL"
Name SDZL1: [8]明细表!$AP$10
Name SDZL1: #REF!
Name SDZL2: [8]明细表!$AQ$10
Name SDZL2: #REF!
Name SDZL3: [8]明细表!$AR$10
Name SDZL3: #REF!
Name SDZL4: [8]明细表!$AS$10
Name SDZL4: #REF!
Name SDZL5: [8]明细表!$AT$10
Name SDZL5: #REF!
Name SDZL6: [9]A5明细表!$AU$30
Name SDZL6: #REF!
Name ssfzxm: '[10]披露表(上市)'!$D$6:$D$15
Name ssfzxm: '[6]披露表(上市)'!$D$6:$D$15
Name u9qphn: [11]出租开发产品明细!$A$1:$I$17
Name UFPrn20051114145239: [12]福利费1!$A$1:$Q$312
Name UFPrn20060224172848: [13]新城资金明细!$A$1:$H$646
Name UFPrn20060224172935: [13]申鑫大厦租金明细!$A$1:$F$570
Name UFPrn20060224173018: [13]三林明细!$A$1:$H$227
Name UFPrn20060224173111: [13]东陆明细!$A$1:$H$274
Name usd: 8.2773
Name 啊: #REF!
Name 啊: '[14]披露表(上市)'!$F$25
Name 报表项目: [15]会计科目表!$C:$C
Name 存货存在: #REF!
Name 存货存在二: #REF!
Name 存货分类: #REF!
Name 存货分类二: #REF!
Name 存货计价和分摊: #REF!
Name 存货计价和分摊二: #REF!
Name 存货截止: #REF!
Name 存货截止二: #REF!
Name 存货列报: #REF!
Name 存货列报二: #REF!
Name 存货权利和义务: #REF!

Sheet 账账核对
A1: 科目编码 | B1: 科目名称 | C1: 科目余额表借方 | D1: 序时账借方 | E1: 借方差额 | F1: 科目余额表贷方 | G1: 序时账贷方 | H1: 贷方差额
A2: {=OFFSET(科目余额表[科目编码],0,0,COUNT(科目余额表[科目编码]),2)} -> 1001 | B2: 库存现金 | C2: =_xlfn.XLOOKUP(A2,科目余额表[科目编码],科目余额表[本期借方],0) -> 0 | D2: =SUMIF(序时账[科目编码],A2,序时账[借方金额]) -> 0 | E2: =C2-D2 -> 0 | F2: =_xlfn.XLOOKUP(A2,科目余额表[科目编码],科目余额表[本期贷方],0) -> 50 | G2: =SUMIF(序时账[科目编码],A2,序时账[贷方金额]) -> 50 | H2: =F2-G2 -> 0
A3: 1002 | B3: 银行存款 | C3: =_xlfn.XLOOKUP(A3,科目余额表[科目编码],科目余额表[本期借方],0) -> 18485749 | D3: =SUMIF(序时账[科目编码],A3,序时账[借方金额]) -> 0 | E3: =C3-D3 -> 18485749 | F3: =_xlfn.XLOOKUP(A3,科目余额表[科目编码],科目余额表[本期贷方],0) -> 5033601.7 | G3: =SUMIF(序时账[科目编码],A3,序时账[贷方金额]) -> 0 | H3: =F3-G3 -> 5033601.7
A4: 1002001 | B4: ABC银行账户 | C4: =_xlfn.XLOOKUP(A4,科目余额表[科目编码],科目余额表[本期借方],0) -> 13194920 | D4: =SUMIF(序时账[科目编码],A4,序时账[借方金额]) -> 13194920 | E4: =C4-D4 -> 0 | F4: =_xlfn.XLOOKUP(A4,科目余额表[科目编码],科目余额表[本期贷方],0) -> 1086601.7 | G4: =SUMIF(序时账[科目编码],A4,序时账[贷方金额]) -> 1086601.7 | H4: =F4-G4 -> 0
A5: 1002002 | B5: EFG银行账户 | C5: =_xlfn.XLOOKUP(A5,科目余额表[科目编码],科目余额表[本期借方],0) -> 5290829.8 | D5: =SUMIF(序时账[科目编码],A5,序时账[借方金额]) -> 5290829.8 | E5: =C5-D5 -> 0 | F5: =_xlfn.XLOOKUP(A5,科目余额表[科目编码],科目余额表[本期贷方],0) -> 3947000 | G5: =SUMIF(序时账[科目编码],A5,序时账[贷方金额]) -> 3947000 | H5: =F5-G5 -> 0
A6: 1122 | B6: 应收账款 | C6: =_xlfn.XLOOKUP(A6,科目余额表[科目编码],科目余额表[本期借方],0) -> 15006400 | D6: =SUMIF(序时账[科目编码],A6,序时账[借方金额]) -> 0 | E6: =C6-D6 -> 15006400 | F6: =_xlfn.XLOOKUP(A6,科目余额表[科目编码],科目余额表[本期贷方],0) -> 12389000 | G6: =SUMIF(序时账[科目编码],A6,序时账[贷方金额]) -> 0 | H6: =F6-G6 -> 12389000
A7: 1122001 | B7: A有限公司 | C7: =_xlfn.XLOOKUP(A7,科目余额表[科目编码],科目余额表[本期借方],0) -> 2395600 | D7: =SUMIF(序时账[科目编码],A7,序时账[借方金额]) -> 2395600 | E7: =C7-D7 -> 0 | F7: =_xlfn.XLOOKUP(A7,科目余额表[科目编码],科目余额表[本期贷方],0) -> 2030000 | G7: =SUMIF(序时账[科目编码],A7,序时账[贷方金额]) -> 2030000 | H7: =F7-G7 -> 0
A8: 1122002 | B8: B有限公司 | C8: =_xlfn.XLOOKUP(A8,科目余额表[科目编码],科目余额表[本期借方],0) -> 1152600 | D8: =SUMIF(序时账[科目编码],A8,序时账[借方金额]) -> 1152600 | E8: =C8-D8 -> 0 | F8: =_xlfn.XLOOKUP(A8,科目余额表[科目编码],科目余额表[本期贷方],0) -> 1029000 | G8: =SUMIF(序时账[科目编码],A8,序时账[贷方金额]) -> 1029000 | H8: =F8-G8 -> 0
A9: 1122003 | B9: C有限公司 | C9: =_xlfn.XLOOKUP(A9,科目余额表[科目编码],科目余额表[本期借方],0) -> 2406900 | D9: =SUMIF(序时账[科目编码],A9,序时账[借方金额]) -> 2406900 | E9: =C9-D9 -> 0 | F9: =_xlfn.XLOOKUP(A9,科目余额表[科目编码],科目余额表[本期贷方],0) -> 1993000 | G9: =SUMIF(序时账[科目编码],A9,序时账[贷方金额]) -> 1993000 | H9: =F9-G9 -> 0
A10: 1122004 | B10: D有限公司 | C10: =_xlfn.XLOOKUP(A10,科目余额表[科目编码],科目余额表[本期借方],0) -> 1175200 | D10: =SUMIF(序时账[科目编码],A10,序时账[借方金额]) -> 1175200 | E10: =C10-D10 -> 0 | F10: =_xlfn.XLOOKUP(A10,科目余额表[科目编码],科目余额表[本期贷方],0) -> 1018000 | G10: =SUMIF(序时账[科目编码],A10,序时账[贷方金额]) -> 1018000 | H10: =F10-G10 -> 0
A11: 1122005 | B11: E有限公司 | C11: =_xlfn.XLOOKUP(A11,科目余额表[科目编码],科目余额表[本期借方],0) -> 1751500 | D11: =SUMIF(序时账[科目编码],A11,序时账[借方金额]) -> 1751500 | E11: =C11-D11 -> 0 | F11: =_xlfn.XLOOKUP(A11,科目余额表[科目编码],科目余额表[本期贷方],0) -> 2009000 | G11: =SUMIF(序时账[科目编码],A11,序时账[贷方金额]) -> 2009000 | H11: =F11-G11 -> 0
A12: 1122006 | B12: F有限公司 | C12: =_xlfn.XLOOKUP(A12,科目余额表[科目编码],科目余额表[本期借方],0) -> 1197800 | D12: =SUMIF(序时账[科目编码],A12,序时账[借方金额]) -> 1197800 | E12: =C12-D12 -> 0 | F12: =_xlfn.XLOOKUP(A12,科目余额表[科目编码],科目余额表[本期贷方],0) -> 870000 | G12: =SUMIF(序时账[科目编码],A12,序时账[贷方金额]) -> 870000 | H12: =F12-G12 -> 0
A13: 1122007 | B13: G有限公司 | C13: =_xlfn.XLOOKUP(A13,科目余额表[科目编码],科目余额表[本期借方],0) -> 1209100 | D13: =SUMIF(序时账[科目编码],A13,序时账[借方金额]) -> 1209100 | E13: =C13-D13 -> 0 | F13: =_xlfn.XLOOKUP(A13,科目余额表[科目编码],科目余额表[本期贷方],0) -> 810000 | G13: =SUMIF(序时账[科目编码],A13,序时账[贷方金额]) -> 810000 | H13: =F13-G13 -> 0
A14: 1122008 | B14: H有限公司 | C14: =_xlfn.XLOOKUP(A14,科目余额表[科目编码],科目余额表[本期借方],0) -> 1220400 | D14: =SUMIF(序时账[科目编码],A14,序时账[借方金额]) -> 1220400 | E14: =C14-D14 -> 0 | F14: =_xlfn.XLOOKUP(A14,科目余额表[科目编码],科目余额表[本期贷方],0) -> 770000 | G14: =SUMIF(序时账[科目编码],A14,序时账[贷方金额]) -> 770000 | H14: =F14-G14 -> 0
... A85: 5801 | B85: 所得税费用 | C85: =_xlfn.XLOOKUP(A85,科目余额表[科目编码],科目余额表[本期借方],0) -> 579779.36 | D85: =SUMIF(序时账[科目编码],A85,序时账[借方金额]) -> 579779.36 | E85: =C85-D85 -> 0 | F85: =_xlfn.XLOOKUP(A85,科目余额表[科目编码],科目余额表[本期贷方],0) -> 579779.36 | G85: =SUMIF(序时账[科目编码],A85,序时账[贷方金额]) -> 579779.36 | H85: =F85-G85 -> 0
C86: =_xlfn.XLOOKUP(A86,科目余额表[科目编码],科目余额表[本期借方],0) -> 0 | D86: =SUMIF(序时账[科目编码],A86,序时账[借方金额]) -> 0 | E86: =C86-D86 -> 0 | F86: =_xlfn.XLOOKUP(A86,科目余额表[科目编码],科目余额表[本期贷方],0) -> 0 | G86: =SUMIF(序时账[科目编码],A86,序时账[贷方金额]) -> 0 | H86: =F86-G86 -> 0
C87: =_xlfn.XLOOKUP(A87,科目余额表[科目编码],科目余额表[本期借方],0) -> 0 | D87: =SUMIF(序时账[科目编码],A87,序时账[借方金额]) -> 0 | E87: =C87-D87 -> 0 | F87: =_xlfn.XLOOKUP(A87,科目余额表[科目编码],科目余额表[本期贷方],0) -> 0 | G87: =SUMIF(序时账[科目编码],A87,序时账[贷方金额]) -> 0 | H87: =F87-G87 -> 0
C88: =_xlfn.XLOOKUP(A88,科目余额表[科目编码],科目余额表[本期借方],0) -> 0 | D88: =SUMIF(序时账[科目编码],A88,序时账[借方金额]) -> 0 | E88: =C88-D88 -> 0 | F88: =_xlfn.XLOOKUP(A88,科目余额表[科目编码],科目余额表[本期贷方],0) -> 0 | G88: =SUMIF(序时账[科目编码],A88,序时账[贷方金额]) -> 0 | H88: =F88-G88 -> 0
C89: =_xlfn.XLOOKUP(A89,科目余额表[科目编码],科目余额表[本期借方],0) -> 0 | D89: =SUMIF(序时账[科目编码],A89,序时账[借方金额]) -> 0 | E89: =C89-D89 -> 0 | F89: =_xlfn.XLOOKUP(A89,科目余额表[科目编码],科目余额表[本期贷方],0) -> 0 | G89: =SUMIF(序时账[科目编码],A89,序时账[贷方金额]) -> 0 | H89: =F89-G89 -> 0
C90: =_xlfn.XLOOKUP(A90,科目余额表[科目编码],科目余额表[本期借方],0) -> 0 | D90: =SUMIF(序时账[科目编码],A90,序时账[借方金额]) -> 0 | E90: =C90-D90 -> 0 | F90: =_xlfn.XLOOKUP(A90,科目余额表[科目编码],科目余额表[本期贷方],0) -> 0 | G90: =SUMIF(序时账[科目编码],A90,序时账[贷方金额]) -> 0 | H90: =F90-G90 -> 0
C91: =_xlfn.XLOOKUP(A91,科目余额表[科目编码],科目余额表[本期借方],0) -> 0 | D91: =SUMIF(序时账[科目编码],A91,序时账[借方金额]) -> 0 | E91: =C91-D91 -> 0 | F91: =_xlfn.XLOOKUP(A91,科目余额表[科目编码],科目余额表[本期贷方],0) -> 0 | G91: =SUMIF(序时账[科目编码],A91,序时账[贷方金额]) -> 0 | H91: =F91-G91 -> 0
C92: =_xlfn.XLOOKUP(A92,科目余额表[科目编码],科目余额表[本期借方],0) -> 0 | D92: =SUMIF(序时账[科目编码],A92,序时账[借方金额]) -> 0 | E92: =C92-D92 -> 0 | F92: =_xlfn.XLOOKUP(A92,科目余额表[科目编码],科目余额表[本期贷方],0) -> 0 | G92: =SUMIF(序时账[科目编码],A92,序时账[贷方金额]) -> 0 | H92: =F92-G92 -> 0
C93: =_xlfn.XLOOKUP(A93,科目余额表[科目编码],科目余额表[本期借方],0) -> 0 | D93: =SUMIF(序时账[科目编码],A93,序时账[借方金额]) -> 0 | E93: =C93-D93 -> 0 | F93: =_xlfn.XLOOKUP(A93,科目余额表[科目编码],科目余额表[本期贷方],0) -> 0 | G93: =SUMIF(序时账[科目编码],A93,序时账[贷方金额]) -> 0 | H93: =F93-G93 -> 0
C94: =_xlfn.XLOOKUP(A94,科目余额表[科目编码],科目余额表[本期借方],0) -> 0 | D94: =SUMIF(序时账[科目编码],A94,序时账[借方金额]) -> 0 | E94: =C94-D94 -> 0 | F94: =_xlfn.XLOOKUP(A94,科目余额表[科目编码],科目余额表[本期贷方],0) -> 0 | G94: =SUMIF(序时账[科目编码],A94,序时账[贷方金额]) -> 0 | H94: =F94-G94 -> 0
C95: =_xlfn.XLOOKUP(A95,科目余额表[科目编码],科目余额表[本期借方],0) -> 0 | D95: =SUMIF(序时账[科目编码],A95,序时账[借方金额]) -> 0 | E95: =C95-D95 -> 0 | F95: =_xlfn.XLOOKUP(A95,科目余额表[科目编码],科目余额表[本期贷方],0) -> 0 | G95: =SUMIF(序时账[科目编码],A95,序时账[贷方金额]) -> 0 | H95: =F95-G95 -> 0
C96: =_xlfn.XLOOKUP(A96,科目余额表[科目编码],科目余额表[本期借方],0) -> 0 | D96: =SUMIF(序时账[科目编码],A96,序时账[借方金额]) -> 0 | E96: =C96-D96 -> 0 | F96: =_xlfn.XLOOKUP(A96,科目余额表[科目编码],科目余额表[本期贷方],0) -> 0 | G96: =SUMIF(序时账[科目编码],A96,序时账[贷方金额]) -> 0 | H96: =F96-G96 -> 0
C97: =_xlfn.XLOOKUP(A97,科目余额表[科目编码],科目余额表[本期借方],0) -> 0 | D97: =SUMIF(序时账[科目编码],A97,序时账[借方金额]) -> 0 | E97: =C97-D97 -> 0 | F97: =_xlfn.XLOOKUP(A97,科目余额表[科目编码],科目余额表[本期贷方],0) -> 0 | G97: =SUMIF(序时账[科目编码],A97,序时账[贷方金额]) -> 0 | H97: =F97-G97 -> 0
... C251: =_xlfn.XLOOKUP(A251,科目余额表[科目编码],科目余额表[本期借方],0) -> 0 | D251: =SUMIF(序时账[科目编码],A251,序时账[借方金额]) -> 0 | E251: =C251-D251 -> 0 | F251: =_xlfn.XLOOKUP(A251,科目余额表[科目编码],科目余额表[本期贷方],0) -> 0 | G251: =SUMIF(序时账[科目编码],A251,序时账[贷方金额]) -> 0 | H251: =F251-G251 -> 0

Sheet 校对表
A1: 资产负债表（期初）
A2: 报表项目 | B2: 报表金额 | C2: 报表项目 | D2: 报表金额
A3: 流动资产合计 | B3: =SUM(试算平衡表!C2:C14) -> 18778262 | C3: 流动负债合计 | D3: =SUM(试算平衡表!C33:C45) -> 6154772.8
A4: 非流动资产合计 | B4: =SUM(试算平衡表!C15:C32) -> 907134.11 | C4: 非流动负债合计 | D4: =SUM(试算平衡表!C46:C54) -> 0
C5: 负债合计 | D5: =SUM(D3:D4) -> 6154772.8
C6: 所有者权益（或股东权益）合计 | D6: =SUM(试算平衡表!C55:C57)-试算平衡表!C58+SUM(试算平衡表!C59:C62) -> 13530623
A7: 资产总计 | B7: =SUM(B3:B6) -> 19685396 | C7: 负债和所有者权益（或股东权益）总计 | D7: =SUM(D5:D6) -> 19685396
A8: 资产负债表（期末）
A9: 报表项目 | B9: 报表金额 | C9: 报表项目 | D9: 报表金额
A10: 流动资产合计 | B10: =SUM(试算平衡表!D2:D14) -> 31234121 | C10: 流动负债合计 | D10: =SUM(试算平衡表!D33:D45) -> 17208982
A11: 非流动资产合计 | B11: =SUM(试算平衡表!D15:D32) -> 1244774.1 | C11: 非流动负债合计 | D11: =SUM(试算平衡表!D46:D54) -> 0
C12: 负债合计 | D12: =SUM(D10:D11) -> 17208982
C13: 所有者权益（或股东权益）合计 | D13: =SUM(试算平衡表!D55:D57)-试算平衡表!D58+SUM(试算平衡表!D59:D62) -> 15269912
A14: 资产总计 | B14: =SUM(B10:B13) -> 32478895 | C14: 负债和所有者权益（或股东权益）总计 | D14: =SUM(D12:D13) -> 32478895
A15: 资产负债表平衡
A16: 期初资产负债表平衡差额 | B16: =B7-D7 -> 0
A17: 期末资产负债表平衡差额 | B17: =B14-D14 -> 0
A18: 利润表
A19: 期初未分配利润 | B19: =试算平衡表!C62 -> 3530623.1
A20: 本期净利润 | B20: =试算平衡表!D63-SUM(试算平衡表!D64:'试算平衡表'!D69)+SUM(试算平衡表!D70:'试算平衡表'!D77)-SUM(试算平衡表!D78:'试算平衡表'!D79) -> 1739289.3
A21: 减：利润分配
A22: 加：其他调整
A23: 减：其他调整
A24: 计算年末未分配利润 | B24: =B19+B20-B21+B22-B23 -> 5269912.4
A25: 报表年末未分配利润 | B25: =试算平衡表!D62 -> 5269912.5
A26: 差额 | B26: =B24-B25 -> 0
A27: 现金流
A28: 项目 | B28: 借方发生额 | C28: 贷方发生额
A29: 科目余额表现金、银行存款、其他货币资金 | B29: =SUMIF(科目余额表!I:I,"货币资金",科目余额表!E:E) -> 18485749 | C29: =SUMIF(科目余额表!I:I,"货币资金",科目余额表!F:F) -> 5033651.7
A30: 序时账现金 | B30: =SUMIF(序时账!I:I,"现金",序时账!G:G) -> 0 | C30: =SUMIF(序时账!I:I,"现金",序时账!H:H) -> 50
A31: 序时账银行存款 | B31: =SUMIF(序时账!I:I,"银行存款",序时账!G:G) -> 18485749 | C31: =SUMIF(序时账!I:I,"银行存款",序时账!H:H) -> 5033601.7
A32: 序时账其他货币资金 | B32: =SUMIF(序时账!I:I,"其他货币资金",序时账!G:G) -> 0 | C32: =SUMIF(序时账!I:I,"其他货币资金",序时账!H:H) -> 0
A33: 差额 | B33: =B29-B30-B31 -> 0 | C33: =C29-C30-C31 -> 0
A34: 往来附注查重
A35: 往来单位 | B35: 是否有重复项
A36: {=_xlfn.UNIQUE(D36:D75)} -> F有限公司 | B36: =IF(COUNTIF($D$36:$D$75,A36)>1,COUNTIF($D$36:$D$75,A36),"—") -> — | C36: 应收账款 | D36: {=OFFSET(附注自动计算!A25:A29,0,0)} -> F有限公司
A37: H有限公司 | B37: =IF(COUNTIF($D$36:$D$75,A37)>1,COUNTIF($D$36:$D$75,A37),"—") -> — | D37: H有限公司
A38: A有限公司 | B38: =IF(COUNTIF($D$36:$D$75,A38)>1,COUNTIF($D$36:$D$75,A38),"—") -> — | D38: A有限公司
A39: I有限公司 | B39: =IF(COUNTIF($D$36:$D$75,A39)>1,COUNTIF($D$36:$D$75,A39),"—") -> — | D39: I有限公司
A40: G有限公司 | B40: =IF(COUNTIF($D$36:$D$75,A40)>1,COUNTIF($D$36:$D$75,A40),"—") -> — | D40: G有限公司
...

Sheet 科目余额表
A1: 科目编码 | B1: 科目名称 | C1: 期初借方 | D1: 期初贷方 | E1: 本期借方 | F1: 本期贷方 | G1: 期末借方 | H1: 期末贷方 | I1: 未审报表项目 | J1: 已审报表项目 | K1: 调整 | L1: 抽查项目 | M1: 测算项目
A2: 1001 | B2: 库存现金 | C2: 15002.34 | D2: 0 | E2: 0 | F2: 50 | G2: 14952.34 | H2: 0 | I2: 货币资金 | J2: 货币资金 | K2: =IF(I2<>J2,"是","否") -> 否 | L2: 现金 | M2: 现金
A3: 1002 | B3: 银行存款 | C3: 995835 | D3: 0 | E3: 18485749 | F3: 5033601.7 | G3: 14447983 | H3: 0 | K3: =IF(I3<>J3,"是","否") -> 否
A4: 1002001 | B4: ABC银行账户 | C4: 955349.35 | D4: 0 | E4: 13194920 | F4: 1086601.7 | G4: 13063667 | H4: 0 | I4: 货币资金 | J4: 货币资金 | K4: =IF(I4<>J4,"是","否") -> 否 | L4: 银行存款 | M4: 银行存款
A5: 1002002 | B5: EFG银行账户 | C5: 40485.65 | D5: 0 | E5: 5290829.8 | F5: 3947000 | G5: 1384315.4 | H5: 0 | I5: 货币资金 | J5: 货币资金 | K5: =IF(I5<>J5,"是","否") -> 否 | L5: 银行存款 | M5: 银行存款
A6: 1122 | B6: 应收账款 | C6: 5547848 | D6: 0 | E6: 15006400 | F6: 12389000 | G6: 8165248 | H6: 0 | K6: =IF(I6<>J6,"是","否") -> 否
A7: 1122001 | B7: A有限公司 | C7: 552444.45 | D7: 0 | E7: 2395600 | F7: 2030000 | G7: 918044.45 | H7: 0 | I7: 应收账款 | J7: 应收账款 | K7: =IF(I7<>J7,"是","否") -> 否 | L7: 应收账款
A8: 1122002 | B8: B有限公司 | C8: 449224.39 | D8: 0 | E8: 1152600 | F8: 1029000 | G8: 572824.39 | H8: 0 | I8: 应收账款 | J8: 应收账款 | K8: =IF(I8<>J8,"是","否") -> 否 | L8: 应收账款
A9: 1122003 | B9: C有限公司 | C9: 228599.99 | D9: 0 | E9: 2406900 | F9: 1993000 | G9: 642499.99 | H9: 0 | I9: 应收账款 | J9: 应收账款 | K9: =IF(I9<>J9,"是","否") -> 否 | L9: 应收账款
A10: 1122004 | B10: D有限公司 | C10: 669788.45 | D10: 0 | E10: 1175200 | F10: 1018000 | G10: 826988.45 | H10: 0 | I10: 应收账款 | J10: 应收账款 | K10: =IF(I10<>J10,"是","否") -> 否 | L10: 应收账款
A11: 1122005 | B11: E有限公司 | C11: 550333.49 | D11: 0 | E11: 1751500 | F11: 2009000 | G11: 292833.49 | H11: 0 | I11: 应收账款 | J11: 应收账款 | K11: =IF(I11<>J11,"是","否") -> 否 | L11: 应收账款
A12: 1122006 | B12: F有限公司 | C12: 999200.88 | D12: 0 | E12: 1197800 | F12: 870000 | G12: 1327000.9 | H12: 0 | I12: 应收账款 | J12: 应收账款 | K12: =IF(I12<>J12,"是","否") -> 否 | L12: 应收账款
A13: 1122007 | B13: G有限公司 | C13: 450055.23 | D13: 0 | E13: 1209100 | F13: 810000 | G13: 849155.23 | H13: 0 | I13: 应收账款 | J13: 应收账款 | K13: =IF(I13<>J13,"是","否") -> 否 | L13: 应收账款
A14: 1122008 | B14: H有限公司 | C14: 555455.34 | D14: 0 | E14: 1220400 | F14: 770000 | G14: 1005855.3 | H14: 0 | I14: 应收账款 | J14: 应收账款 | K14: =IF(I14<>J14,"是","否") -> 否 | L14: 应收账款
A15: 1122009 | B15: I有限公司 | C15: 566229.43 | D15: 0 | E15: 1231700 | F15: 880000 | G15: 917929.43 | H15: 0 | I15: 应收账款 | J15: 应收账款 | K15: =IF(I15<>J15,"是","否") -> 否 | L15: 应收账款
A16: 1122010 | B16: J有限公司 | C16: 526516.34 | D16: 0 | E16: 1265600 | F16: 980000 | G16: 812116.34 | H16: 0 | I16: 应收账款 | J16: 应收账款 | K16: =IF(I16<>J16,"是","否") -> 否 | L16: 应收账款
A17: 1123 | B17: 预付账款 | C17: 2001987.2 | D17: 0 | E17: 540000 | F17: 4869264 | G17: -2327276.8 | H17: 0 | K17: =IF(I17<>J17,"是","否") -> 否
A18: 1123001 | B18: K有限公司 | C18: 200199.49 | D18: 0 | E18: 0 | F18: 568842 | G18: -368642.51 | H18: 0 | I18: 预付款项 | J18: 应付账款 | K18: =IF(I18<>J18,"是","否") -> 是 | L18: 预付款项
A19: 1123002 | B19: L有限公司 | C19: 188355.45 | D19: 0 | E19: 0 | F19: 698000 | G19: -509644.55 | H19: 0 | I19: 预付款项 | J19: 应付账款 | K19: =IF(I19<>J19,"是","否") -> 是 | L19: 预付款项
A20: 1123003 | B20: M有限公司 | C20: 422009.32 | D20: 0 | E20: 0 | F20: 568842 | G20: -146832.68 | H20: 0 | I20: 预付款项 | J20: 应付账款 | K20: =IF(I20<>J20,"是","否") -> 是 | L20: 预付款项
A21: 1123004 | B21: N有限公司 | C21: 334588.9 | D21: 0 | E21: 0 | F21: 0 | G21: 334588.9 | H21: 0 | I21: 预付款项 | J21: 预付款项 | K21: =IF(I21<>J21,"是","否") -> 否 | L21: 预付款项
A22: 1123005 | B22: C有限公司 | C22: 235333.35 | D22: 0 | E22: 0 | F22: 1361700 | G22: -1126366.6 | H22: 0 | I22: 预付款项 | J22: 应付账款 | K22: =IF(I22<>J22,"是","否") -> 是 | L22: 预付款项
A23: 1123006 | B23: O有限公司 | C23: 190048.34 | D23: 0 | E23: 540000 | F23: 0 | G23: 730048.34 | H23: 0 | I23: 预付款项 | J23: 预付款项 | K23: =IF(I23<>J23,"是","否") -> 否 | L23: 预付款项
A24: 1123007 | B24: P有限公司 | C24: 230444.39 | D24: 0 | E24: 0 | F24: 763880 | G24: -533435.61 | H24: 0 | I24: 预付款项 | J24: 应付账款 | K24: =IF(I24<>J24,"是","否") -> 是 | L24: 预付款项
A25: 1123008 | B25: Q有限公司 | C25: 201008 | D25: 0 | E25: 0 | F25: 908000 | G25: -706992 | H25: 0 | I25: 预付款项 | J25: 应付账款 | K25: =IF(I25<>J25,"是","否") -> 是 | L25: 预付款项
A26: 1221 | B26: 其他应收款 | C26: 229934.57 | D26: 0 | E26: 0 | F26: 10000 | G26: 219934.57 | H26: 0 | K26: =IF(I26<>J26,"是","否") -> 否
A27: 1221001 | B27: 张三 | C27: 78922.34 | D27: 0 | E27: 0 | F27: 0 | G27: 78922.34 | H27: 0 | I27: 其他应收款 | J27: 其他应收款 | K27: =IF(I27<>J27,"是","否") -> 否 | L27: 其他应收款
A28: 1221002 | B28: 李四 | C28: 68847.87 | D28: 0 | E28: 0 | F28: 10000 | G28: 58847.87 | H28: 0 | I28: 其他应收款 | J28: 其他应收款 | K28: =IF(I28<>J28,"是","否") -> 否 | L28: 其他应收款
A29: 1221003 | B29: 王五 | C29: 82164.36 | D29: 0 | E29: 0 | F29: 0 | G29: 82164.36 | H29: 0 | I29: 其他应收款 | J29: 其他应收款 | K29: =IF(I29<>J29,"是","否") -> 否 | L29: 其他应收款
A30: 1405 | B30: 库存商品 | C30: 9987654.7 | D30: 0 | E30: 8546300 | F30: 10878000 | G30: 7655954.7 | H30: 0 | K30: =IF(I30<>J30,"是","否") -> 否
A31: 1405001 | B31: R商品 | C31: 4590388.5 | D31: 0 | E31: 5826500 | F31: 5436000 | G31: 4980888.5 | H31: 0 | I31: 存货 | J31: 存货 | K31: =IF(I31<>J31,"是","否") -> 否 | L31: 存货
A32: 1405002 | B32: S商品 | C32: 5397266.2 | D32: 0 | E32: 2719800 | F32: 5442000 | G32: 2675066.2 | H32: 0 | I32: 存货 | J32: 存货 | K32: =IF(I32<>J32,"是","否") -> 否 | L32: 存货
A33: 1601 | B33: 固定资产 | C33: 2007689 | D33: 0 | E33: 350000 | F33: 0 | G33: 2357689 | H33: 0 | K33: =IF(I33<>J33,"是","否") -> 否
A34: 1601001 | B34: 轿车 | C34: 1877654.6 | D34: 0 | E34: 350000 | F34: 0 | G34: 2227654.6 | H34: 0 | I34: 固定资产 | J34: 固定资产 | K34: =IF(I34<>J34,"是","否") -> 否 | L34: 固定资产 | M34: 固-运输工具
A35: 1601002 | B35: 电脑 | C35: 130034.38 | D35: 0 | E35: 0 | F35: 0 | G35: 130034.38 | H35: 0 | I35: 固定资产 | J35: 固定资产 | K35: =IF(I35<>J35,"是","否") -> 否 | L35: 固定资产 | M35: 固-电子设备
A36: 1602 | B36: 累计折旧 | C36: 0 | D36: 1100554.9 | E36: 0 | F36: 12360 | G36: 0 | H36: 1112914.9 | K36: =IF(I36<>J36,"是","否") -> 否
A37: 1602001 | B37: 轿车 | C37: 0 | D37: 1034677.5 | E37: 0 | F37: 0 | G37: 0 | H37: 1044677.5 | I37: 固定资产 | J37: 固定资产 | K37: =IF(I37<>J37,"是","否") -> 否 | L37: 固定资产 | M37: 折-运输工具
A38: 1602002 | B38: 电脑 | C38: 0 | D38: 65877.34 | E38: 0 | F38: 12360 | G38: 0 | H38: 68237.34 | I38: 固定资产 | J38: 固定资产 | K38: =IF(I38<>J38,"是","否") -> 否 | L38: 固定资产 | M38: 折-电子设备
A39: 2202 | B39: 应付账款 | C39: 0 | D39: 5678890.3 | E39: 3400000 | F39: 10866055 | G39: 0 | H39: 13144945 | K39: =IF(I39<>J39,"是","否") -> 否
A40: 2202001 | B40: T有限公司 | C40: 0 | D40: 566399.29 | E40: 0 | F40: 1566604 | G40: 0 | H40: 2133003.3 | I40: 应付账款 | J40: 应付账款 | K40: =IF(I40<>J40,"是","否") -> 否 | L40: 应付账款
...

Sheet 序时账
A1: 涉及科目 | B1: 日期 | C1: 凭证字号 | D1: 科目编码 | E1: 科目名称 | F1: 摘要 | G1: 借方金额 | H1: 贷方金额 | I1: 抽查项目 | J1: 对方科目 | K1: 现金流分类 | L1: 测算项目 | M1: 测算金额
A2: {=_xlfn.TEXTJOIN(",", TRUE, _xlfn.UNIQUE(IF((序时账[日期]=B2)*(序时账[凭证字号]=C2), 序时账[科目编码], "")))} -> 5602001,1602002 | B2: 45667 | C2: 1 | D2: 5602001 | E2: 管理费用-折旧费 | F2: 计提折旧费用 | G2: 1030 | H2: 0 | I2: =IF(F2<>"结转本期损益",_xlfn.XLOOKUP(D2,科目余额表[科目编码],科目余额表[抽查项目],"无匹配"),"期间结转") -> 管理费用 | J2: {=_xlfn.TEXTJOIN(",", TRUE, _xlfn.UNIQUE(IF((序时账[日期]=B2)*(序时账[凭证字号]=C2)*IF(G2=0,序时账[借方金额]<>0,序时账[借方金额]=0)*(序时账[科目编码]<>D2), 序时账[科目名称], "")))} -> 电脑
A3: {=_xlfn.TEXTJOIN(",", TRUE, _xlfn.UNIQUE(IF((序时账[日期]=B3)*(序时账[凭证字号]=C3), 序时账[科目编码], "")))} -> 5602001,1602002 | B3: 45667 | C3: 1 | D3: 1602002 | E3: 电脑 | F3: 计提折旧费用 | G3: 0 | H3: 1030 | I3: =IF(F3<>"结转本期损益",_xlfn.XLOOKUP(D3,科目余额表[科目编码],科目余额表[抽查项目],"无匹配"),"期间结转") -> 固定资产 | J3: {=_xlfn.TEXTJOIN(",", TRUE, _xlfn.UNIQUE(IF((序时账[日期]=B3)*(序时账[凭证字号]=C3)*IF(G3=0,序时账[借方金额]<>0,序时账[借方金额]=0)*(序时账[科目编码]<>D3), 序时账[科目名称], "")))} -> 管理费用-折旧费
A4: {=_xlfn.TEXTJOIN(",", TRUE, _xlfn.UNIQUE(IF((序时账[日期]=B4)*(序时账[凭证字号]=C4), 序时账[科目编码], "")))} -> 1122001,5001,222100102 | B4: 45672 | C4: 2 | D4: 1122001 | E4: 应收账款-A有限公司 | F4: 销售收入 | G4: 1141300 | H4: 0 | I4: =IF(F4<>"结转本期损益",_xlfn.XLOOKUP(D4,科目余额表[科目编码],科目余额表[抽查项目],"无匹配"),"期间结转") -> 应收账款 | J4: {=_xlfn.TEXTJOIN(",", TRUE, _xlfn.UNIQUE(IF((序时账[日期]=B4)*(序时账[凭证字号]=C4)*IF(G4=0,序时账[借方金额]<>0,序时账[借方金额]=0)*(序时账[科目编码]<>D4), 序时账[科目名称], "")))} -> 主营业务收入,销项税额
A5: {=_xlfn.TEXTJOIN(",", TRUE, _xlfn.UNIQUE(IF((序时账[日期]=B5)*(序时账[凭证字号]=C5), 序时账[科目编码], "")))} -> 1122001,5001,222100102 | B5: 45672 | C5: 2 | D5: 5001 | E5: 主营业务收入 | F5: 销售收入 | G5: 0 | H5: 1010000 | I5: =IF(F5<>"结转本期损益",_xlfn.XLOOKUP(D5,科目余额表[科目编码],科目余额表[抽查项目],"无匹配"),"期间结转") -> 营业收入 | J5: {=_xlfn.TEXTJOIN(",", TRUE, _xlfn.UNIQUE(IF((序时账[日期]=B5)*(序时账[凭证字号]=C5)*IF(G5=0,序时账[借方金额]<>0,序时账[借方金额]=0)*(序时账[科目编码]<>D5), 序时账[科目名称], "")))} -> 应收账款-A有限公司
A6: {=_xlfn.TEXTJOIN(",", TRUE, _xlfn.UNIQUE(IF((序时账[日期]=B6)*(序时账[凭证字号]=C6), 序时账[科目编码], "")))} -> 1122001,5001,222100102 | B6: 45672 | C6: 2 | D6: 222100102 | E6: 销项税额 | F6: 销售收入 | G6: 0 | H6: 131300 | I6: =IF(F6<>"结转本期损益",_xlfn.XLOOKUP(D6,科目余额表[科目编码],科目余额表[抽查项目],"无匹配"),"期间结转") -> 应交税费 | J6: {=_xlfn.TEXTJOIN(",", TRUE, _xlfn.UNIQUE(IF((序时账[日期]=B6)*(序时账[凭证字号]=C6)*IF(G6=0,序时账[借方金额]<>0,序时账[借方金额]=0)*(序时账[科目编码]<>D6), 序时账[科目名称], "")))} -> 应收账款-A有限公司
A7: {=_xlfn.TEXTJOIN(",", TRUE, _xlfn.UNIQUE(IF((序时账[日期]=B7)*(序时账[凭证字号]=C7), 序时账[科目编码], "")))} -> 5401,1405001 | B7: 45672 | C7: 3 | D7: 5401 | E7: 主营业务成本 | F7: 结转销售成本 | G7: 901000 | H7: 0 | I7: =IF(F7<>"结转本期损益",_xlfn.XLOOKUP(D7,科目余额表[科目编码],科目余额表[抽查项目],"无匹配"),"期间结转") -> 营业成本 | J7: {=_xlfn.TEXTJOIN(",", TRUE, _xlfn.UNIQUE(IF((序时账[日期]=B7)*(序时账[凭证字号]=C7)*IF(G7=0,序时账[借方金额]<>0,序时账[借方金额]=0)*(序时账[科目编码]<>D7), 序时账[科目名称], "")))} -> R商品
A8: {=_xlfn.TEXTJOIN(",", TRUE, _xlfn.UNIQUE(IF((序时账[日期]=B8)*(序时账[凭证字号]=C8), 序时账[科目编码], "")))} -> 5401,1405001 | B8: 45672 | C8: 3 | D8: 1405001 | E8: R商品 | F8: 结转销售成本 | G8: 0 | H8: 901000 | I8: =IF(F8<>"结转本期损益",_xlfn.XLOOKUP(D8,科目余额表[科目编码],科目余额表[抽查项目],"无匹配"),"期间结转") -> 存货 | J8: {=_xlfn.TEXTJOIN(",", TRUE, _xlfn.UNIQUE(IF((序时账[日期]=B8)*(序时账[凭证字号]=C8)*IF(G8=0,序时账[借方金额]<>0,序时账[借方金额]=0)*(序时账[科目编码]<>D8), 序时账[科目名称], "")))} -> 主营业务成本
A9: {=_xlfn.TEXTJOIN(",", TRUE, _xlfn.UNIQUE(IF((序时账[日期]=B9)*(序时账[凭证字号]=C9), 序时账[科目编码], "")))} -> 1002001,1122001 | B9: 45677 | C9: 4 | D9: 1002001 | E9: ABC银行账户 | F9: 收货款 | G9: 2030000 | H9: 0 | I9: =IF(F9<>"结转本期损益",_xlfn.XLOOKUP(D9,科目余额表[科目编码],科目余额表[抽查项目],"无匹配"),"期间结转") -> 银行存款 | J9: {=_xlfn.TEXTJOIN(",", TRUE, _xlfn.UNIQUE(IF((序时账[日期]=B9)*(序时账[凭证字号]=C9)*IF(G9=0,序时账[借方金额]<>0,序时账[借方金额]=0)*(序时账[科目编码]<>D9), 序时账[科目名称], "")))} -> 应收账款-A有限公司 | K9: 应收账款-A有限公司
A10: {=_xlfn.TEXTJOIN(",", TRUE, _xlfn.UNIQUE(IF((序时账[日期]=B10)*(序时账[凭证字号]=C10), 序时账[科目编码], "")))} -> 1002001,1122001 | B10: 45677 | C10: 4 | D10: 1122001 | E10: 应收账款-A有限公司 | F10: 收货款 | G10: 0 | H10: 2030000 | I10: =IF(F10<>"结转本期损益",_xlfn.XLOOKUP(D10,科目余额表[科目编码],科目余额表[抽查项目],"无匹配"),"期间结转") -> 应收账款 | J10: {=_xlfn.TEXTJOIN(",", TRUE, _xlfn.UNIQUE(IF((序时账[日期]=B10)*(序时账[凭证字号]=C10)*IF(G10=0,序时账[借方金额]<>0,序时账[借方金额]=0)*(序时账[科目编码]<>D10), 序时账[科目名称], "")))} -> ABC银行账户
A11: {=_xlfn.TEXTJOIN(",", TRUE, _xlfn.UNIQUE(IF((序时账[日期]=B11)*(序时账[凭证字号]=C11), 序时账[科目编码], "")))} -> 1405001,222100101,2202001 | B11: 45677 | C11: 5 | D11: 1405001 | E11: R商品 | F11: 购货 | G11: 490800 | H11: 0 | I11: =IF(F11<>"结转本期损益",_xlfn.XLOOKUP(D11,科目余额表[科目编码],科目余额表[抽查项目],"无匹配"),"期间结转") -> 存货 | J11: {=_xlfn.TEXTJOIN(",", TRUE, _xlfn.UNIQUE(IF((序时账[日期]=B11)*(序时账[凭证字号]=C11)*IF(G11=0,序时账[借方金额]<>0,序时账[借方金额]=0)*(序时账[科目编码]<>D11), 序时账[科目名称], "")))} -> 应付账款-T有限公司
A12: {=_xlfn.TEXTJOIN(",", TRUE, _xlfn.UNIQUE(IF((序时账[日期]=B12)*(序时账[凭证字号]=C12), 序时账[科目编码], "")))} -> 1405001,222100101,2202001 | B12: 45677 | C12: 5 | D12: 222100101 | E12: 进项税额 | F12: 购货 | G12: 63804 | H12: 0 | I12: =IF(F12<>"结转本期损益",_xlfn.XLOOKUP(D12,科目余额表[科目编码],科目余额表[抽查项目],"无匹配"),"期间结转") -> 应交税费 | J12: {=_xlfn.TEXTJOIN(",", TRUE, _xlfn.UNIQUE(IF((序时账[日期]=B12)*(序时账[凭证字号]=C12)*IF(G12=0,序时账[借方金额]<>0,序时账[借方金额]=0)*(序时账[科目编码]<>D12), 序时账[科目名称], "")))} -> 应付账款-T有限公司
A13: {=_xlfn.TEXTJOIN(",", TRUE, _xlfn.UNIQUE(IF((序时账[日期]=B13)*(序时账[凭证字号]=C13), 序时账[科目编码], "")))} -> 1405001,222100101,2202001 | B13: 45677 | C13: 5 | D13: 2202001 | E13: 应付账款-T有限公司 | F13: 购货 | G13: 0 | H13: 554604 | I13: =IF(F13<>"结转本期损益",_xlfn.XLOOKUP(D13,科目余额表[科目编码],科目余额表[抽查项目],"无匹配"),"期间结转") -> 应付账款 | J13: {=_xlfn.TEXTJOIN(",", TRUE, _xlfn.UNIQUE(IF((序时账[日期]=B13)*(序时账[凭证字号]=C13)*IF(G13=0,序时账[借方金额]<>0,序时账[借方金额]=0)*(序时账[科目编码]<>D13), 序时账[科目名称], "")))} -> R商品,进项税额
A14: {=_xlfn.TEXTJOIN(",", TRUE, _xlfn.UNIQUE(IF((序时账[日期]=B14)*(序时账[凭证字号]=C14), 序时账[科目编码], "")))} -> 1002001,2202001 | B14: 45677 | C14: 6 | D14: 1002001 | E14: ABC银行账户 | F14: 付货款 | G14: 1012000 | H14: 0 | I14: =IF(F14<>"结转本期损益",_xlfn.XLOOKUP(D14,科目余额表[科目编码],科目余额表[抽查项目],"无匹配"),"期间结转") -> 银行存款 | J14: {=_xlfn.TEXTJOIN(",", TRUE, _xlfn.UNIQUE(IF((序时账[日期]=B14)*(序时账[凭证字号]=C14)*IF(G14=0,序时账[借方金额]<>0,序时账[借方金额]=0)*(序时账[科目编码]<>D14), 序时账[科目名称], "")))} -> 应付账款-T有限公司 | K14: 应付账款-T有限公司
A15: {=_xlfn.TEXTJOIN(",", TRUE, _xlfn.UNIQUE(IF((序时账[日期]=B15)*(序时账[凭证字号]=C15), 序时账[科目编码], "")))} -> 1002001,2202001 | B15: 45677 | C15: 6 | D15: 2202001 | E15: 应付账款-T有限公司 | F15: 付货款 | G15: 0 | H15: 1012000 | I15: =IF(F15<>"结转本期损益",_xlfn.XLOOKUP(D15,科目余额表[科目编码],科目余额表[抽查项目],"无匹配"),"期间结转") -> 应付账款 | J15: {=_xlfn.TEXTJOIN(",", TRUE, _xlfn.UNIQUE(IF((序时账[日期]=B15)*(序时账[凭证字号]=C15)*IF(G15=0,序时账[借方金额]<>0,序时账[借方金额]=0)*(序时账[科目编码]<>D15), 序时账[科目名称], "")))} -> ABC银行账户
A16: {=_xlfn.TEXTJOIN(",", TRUE, _xlfn.UNIQUE(IF((序时账[日期]=B16)*(序时账[凭证字号]=C16), 序时账[科目编码], "")))} -> 222100102,222100103,222100101,2221002 | B16: 45682 | C16: 7 | D16: 222100102 | E16: 销项税额 | F16: 转出未交增值税 | G16: 131300 | H16: 0 | I16: =IF(F16<>"结转本期损益",_xlfn.XLOOKUP(D16,科目余额表[科目编码],科目余额表[抽查项目],"无匹配"),"期间结转") -> 应交税费 | J16: {=_xlfn.TEXTJOIN(",", TRUE, _xlfn.UNIQUE(IF((序时账[日期]=B16)*(序时账[凭证字号]=C16)*IF(G16=0,序时账[借方金额]<>0,序时账[借方金额]=0)*(序时账[科目编码]<>D16), 序时账[科目名称], "")))} -> 转出未交增值税,进项税额,未交增值税
A17: {=_xlfn.TEXTJOIN(",", TRUE, _xlfn.UNIQUE(IF((序时账[日期]=B17)*(序时账[凭证字号]=C17), 序时账[科目编码], "")))} -> 222100102,222100103,222100101,2221002 | B17: 45682 | C17: 7 | D17: 222100103 | E17: 转出未交增值税 | F17: 转出未交增值税 | G17: 0 | H17: 131300 | I17: =IF(F17<>"结转本期损益",_xlfn.XLOOKUP(D17,科目余额表[科目编码],科目余额表[抽查项目],"无匹配"),"期间结转") -> 应交税费 | J17: {=_xlfn.TEXTJOIN(",", TRUE, _xlfn.UNIQUE(IF((序时账[日期]=B17)*(序时账[凭证字号]=C17)*IF(G17=0,序时账[借方金额]<>0,序时账[借方金额]=0)*(序时账[科目编码]<>D17), 序时账[科目名称], "")))} -> 销项税额
A18: {=_xlfn.TEXTJOIN(",", TRUE, _xlfn.UNIQUE(IF((序时账[日期]=B18)*(序时账[凭证字号]=C18), 序时账[科目编码], "")))} -> 222100102,222100103,222100101,2221002 | B18: 45682 | C18: 7 | D18: 222100103 | E18: 转出未交增值税 | F18: 转出未交增值税 | G18: 63804 | H18: 0 | I18: =IF(F18<>"结转本期损益",_xlfn.XLOOKUP(D18,科目余额表[科目编码],科目余额表[抽查项目],"无匹配"),"期间结转") -> 应交税费 | J18: {=_xlfn.TEXTJOIN(",", TRUE, _xlfn.UNIQUE(IF((序时账[日期]=B18)*(序时账[凭证字号]=C18)*IF(G18=0,序时账[借方金额]<>0,序时账[借方金额]=0)*(序时账[科目编码]<>D18), 序时账[科目名称], "")))} -> 进项税额,未交增值税
A19: {=_xlfn.TEXTJOIN(",", TRUE, _xlfn.UNIQUE(IF((序时账[日期]=B19)*(序时账[凭证字号]=C19), 序时账[科目编码], "")))} -> 222100102,222100103,222100101,2221002 | B19: 45682 | C19: 7 | D19: 222100101 | E19: 进项税额 | F19: 转出未交增值税 | G19: 0 | H19: 63804 | I19: =IF(F19<>"结转本期损益",_xlfn.XLOOKUP(D19,科目余额表[科目编码],科目余额表[抽查项目],"无匹配"),"期间结转") -> 应交税费 | J19: {=_xlfn.TEXTJOIN(",", TRUE, _xlfn.UNIQUE(IF((序时账[日期]=B19)*(序时账[凭证字号]=C19)*IF(G19=0,序时账[借方金额]<>0,序时账[借方金额]=0)*(序时账[科目编码]<>D19), 序时账[科目名称], "")))} -> 销项税额,转出未交增值税
A20: {=_xlfn.TEXTJOIN(",", TRUE, _xlfn.UNIQUE(IF((序时账[日期]=B20)*(序时账[凭证字号]=C20), 序时账[科目编码], "")))} -> 222100102,222100103,222100101,2221002 | B20: 45682 | C20: 7 | D20: 222100103 | E20: 转出未交增值税 | F20: 转出未交增值税 | G20: 67496 | H20: 0 | I20: =IF(F20<>"结转本期损益",_xlfn.XLOOKUP(D20,科目余额表[科目编码],科目余额表[抽查项目],"无匹配"),"期间结转") -> 应交税费 | J20: {=_xlfn.TEXTJOIN(",", TRUE, _xlfn.UNIQUE(IF((序时账[日期]=B20)*(序时账[凭证字号]=C20)*IF(G20=0,序时账[借方金额]<>0,序时账[借方金额]=0)*(序时账[科目编码]<>D20), 序时账[科目名称], "")))} -> 进项税额,未交增值税
A21: {=_xlfn.TEXTJOIN(",", TRUE, _xlfn.UNIQUE(IF((序时账[日期]=B21)*(序时账[凭证字号]=C21), 序时账[科目编码], "")))} -> 222100102,222100103,222100101,2221002 | B21: 45682 | C21: 7 | D21: 2221002 | E21: 未交增值税 | F21: 转出未交增值税 | G21: 0 | H21: 67496 | I21: =IF(F21<>"结转本期损益",_xlfn.XLOOKUP(D21,科目余额表[科目编码],科目余额表[抽查项目],"无匹配"),"期间结转") -> 应交税费 | J21: {=_xlfn.TEXTJOIN(",", TRUE, _xlfn.UNIQUE(IF((序时账[日期]=B21)*(序时账[凭证字号]=C21)*IF(G21=0,序时账[借方金额]<>0,序时账[借方金额]=0)*(序时账[科目编码]<>D21), 序时账[科目名称], "")))} -> 销项税额,转出未交增值税
A22: {=_xlfn.TEXTJOIN(",", TRUE, _xlfn.UNIQUE(IF((序时账[日期]=B22)*(序时账[凭证字号]=C22), 序时账[科目编码], "")))} -> 5403001,5403002,5403003,2221003,2221004,2221005 | B22: 45682 | C22: 8 | D22: 5403001 | E22: 城市维护建设税 | F22: 增值税附税 | G22: 4724.72 | H22: 0 | I22: =IF(F22<>"结转本期损益",_xlfn.XLOOKUP(D22,科目余额表[科目编码],科目余额表[抽查项目],"无匹配"),"期间结转") -> 税金及附加 | J22: {=_xlfn.TEXTJOIN(",", TRUE, _xlfn.UNIQUE(IF((序时账[日期]=B22)*(序时账[凭证字号]=C22)*IF(G22=0,序时账[借方金额]<>0,序时账[借方金额]=0)*(序时账[科目编码]<>D22), 序时账[科目名称], "")))} -> 城市维护建设税,教育费附加,地方教育费附加
A23: {=_xlfn.TEXTJOIN(",", TRUE, _xlfn.UNIQUE(IF((序时账[日期]=B23)*(序时账[凭证字号]=C23), 序时账[科目编码], "")))} -> 5403001,5403002,5403003,2221003,2221004,2221005 | B23: 45682 | C23: 8 | D23: 5403002 | E23: 教育费附加 | F23: 增值税附税 | G23: 2024.88 | H23: 0 | I23: =IF(F23<>"结转本期损益",_xlfn.XLOOKUP(D23,科目余额表[科目编码],科目余额表[抽查项目],"无匹配"),"期间结转") -> 税金及附加 | J23: {=_xlfn.TEXTJOIN(",", TRUE, _xlfn.UNIQUE(IF((序时账[日期]=B23)*(序时账[凭证字号]=C23)*IF(G23=0,序时账[借方金额]<>0,序时账[借方金额]=0)*(序时账[科目编码]<>D23), 序时账[科目名称], "")))} -> 城市维护建设税,教育费附加,地方教育费附加
A24: {=_xlfn.TEXTJOIN(",", TRUE, _xlfn.UNIQUE(IF((序时账[日期]=B24)*(序时账[凭证字号]=C24), 序时账[科目编码], "")))} -> 5403001,5403002,5403003,2221003,2221004,2221005 | B24: 45682 | C24: 8 | D24: 5403003 | E24: 地方教育费附加 | F24: 增值税附税 | G24: 1349.92 | H24: 0 | I24: =IF(F24<>"结转本期损益",_xlfn.XLOOKUP(D24,科目余额表[科目编码],科目余额表[抽查项目],"无匹配"),"期间结转") -> 税金及附加 | J24: {=_xlfn.TEXTJOIN(",", TRUE, _xlfn.UNIQUE(IF((序时账[日期]=B24)*(序时账[凭证字号]=C24)*IF(G24=0,序时账[借方金额]<>0,序时账[借方金额]=0)*(序时账[科目编码]<>D24), 序时账[科目名称], "")))} -> 城市维护建设税,教育费附加,地方教育费附加
A25: {=_xlfn.TEXTJOIN(",", TRUE, _xlfn.UNIQUE(IF((序时账[日期]=B25)*(序时账[凭证字号]=C25), 序时账[科目编码], "")))} -> 5403001,5403002,5403003,2221003,2221004,2221005 | B25: 45682 | C25: 8 | D25: 2221003 | E25: 城市维护建设税 | F25: 增值税附税 | G25: 0 | H25: 4724.72 | I25: =IF(F25<>"结转本期损益",_xlfn.XLOOKUP(D25,科目余额表[科目编码],科目余额表[抽查项目],"无匹配"),"期间结转") -> 应交税费 | J25: {=_xlfn.TEXTJOIN(",", TRUE, _xlfn.UNIQUE(IF((序时账[日期]=B25)*(序时账[凭证字号]=C25)*IF(G25=0,序时账[借方金额]<>0,序时账[借方金额]=0)*(序时账[科目编码]<>D25), 序时账[科目名称], "")))} -> 城市维护建设税,教育费附加,地方教育费附加
A26: {=_xlfn.TEXTJOIN(",", TRUE, _xlfn.UNIQUE(IF((序时账[日期]=B26)*(序时账[凭证字号]=C26), 序时账[科目编码], "")))} -> 5403001,5403002,5403003,2221003,2221004,2221005 | B26: 45682 | C26: 8 | D26: 2221004 | E26: 教育费附加 | F26: 增值税附税 | G26: 0 | H26: 2024.88 | I26: =IF(F26<>"结转本期损益",_xlfn.XLOOKUP(D26,科目余额表[科目编码],科目余额表[抽查项目],"无匹配"),"期间结转") -> 应交税费 | J26: {=_xlfn.TEXTJOIN(",", TRUE, _xlfn.UNIQUE(IF((序时账[日期]=B26)*(序时账[凭证字号]=C26)*IF(G26=0,序时账[借方金额]<>0,序时账[借方金额]=0)*(序时账[科目编码]<>D26), 序时账[科目名称], "")))} -> 城市维护建设税,教育费附加,地方教育费附加
... A31: {=_xlfn.TEXTJOIN(",", TRUE, _xlfn.UNIQUE(IF((序时账[日期]=B31)*(序时账[凭证字号]=C31), 序时账[科目编码], "")))} -> 2221002,2221003,2221004,2221005,1002001 | B31: 45682 | C31: 9 | D31: 2221005 | E31: 地方教育费附加 | F31: 缴税 | G31: 330.33 | H31: 0 | I31: =IF(F31<>"结转本期损益",_xlfn.XLOOKUP(D31,科目余额表[科目编码],科目余额表[抽查项目],"无匹配"),"期间结转") -> 应交税费 | J31: {=_xlfn.TEXTJOIN(",", TRUE, _xlfn.UNIQUE(IF((序时账[日期]=B31)*(序时账[凭证字号]=C31)*IF(G31=0,序时账[借方金额]<>0,序时账[借方金额]=0)*(序时账[科目编码]<>D31), 序时账[科目名称], "")))} -> ABC银行账户
A32: {=_xlfn.TEXTJOIN(",", TRUE, _xlfn.UNIQUE(IF((序时账[日期]=B32)*(序时账[凭证字号]=C32), 序时账[科目编码], "")))} -> 2221002,2221003,2221004,2221005,1002001 | B32: 45682 | C32: 9 | D32: 1002001 | E32: ABC银行账户 | F32: 缴税 | G32: 0 | H32: 18498.46 | I32: =IF(F32<>"结转本期损益",_xlfn.XLOOKUP(D32,科目余额表[科目编码],科目余额表[抽查项目],"无匹配"),"期间结转") -> 银行存款 | J32: {=_xlfn.TEXTJOIN(",", TRUE, _xlfn.UNIQUE(IF((序时账[日期]=B32)*(序时账[凭证字号]=C32)*IF(G32=0,序时账[借方金额]<>0,序时账[借方金额]=0)*(序时账[科目编码]<>D32), 序时账[科目名称], "")))} -> 未交增值税,城市维护建设税,教育费附加,地方教育费附加 | K32: 未交增值税
A33: {=_xlfn.TEXTJOIN(",", TRUE, _xlfn.UNIQUE(IF((序时账[日期]=B33)*(序时账[凭证字号]=C33), 序时账[科目编码], "")))} -> 2221006,1002001 | B33: 45687 | C33: 10 | D33: 2221006 | E33: 企业所得税 | F33: 缴纳企业所得税 | G33: 111385.32 | H33: 0 | I33: =IF(F33<>"结转本期损益",_xlfn.XLOOKUP(D33,科目余额表[科目编码],科目余额表[抽查项目],"无匹配"),"期间结转") -> 应交税费 | J33: {=_xlfn.TEXTJOIN(",", TRUE, _xlfn.UNIQUE(IF((序时账[日期]=B33)*(序时账[凭证字号]=C33)*IF(G33=0,序时账[借方金额]<>0,序时账[借方金额]=0)*(序时账[科目编码]<>D33), 序时账[科目名称], "")))} -> ABC银行账户
A34: {=_xlfn.TEXTJOIN(",", TRUE, _xlfn.UNIQUE(IF((序时账[日期]=B34)*(序时账[凭证字号]=C34), 序时账[科目编码], "")))} -> 2221006,1002001 | B34: 45687 | C34: 10 | D34: 1002001 | E34: ABC银行账户 | F34: 缴纳企业所得税 | G34: 0 | H34: 111385.32 | I34: =IF(F34<>"结转本期损益",_xlfn.XLOOKUP(D34,科目余额表[科目编码],科目余额表[抽查项目],"无匹配"),"期间结转") -> 银行存款 | J34: {=_xlfn.TEXTJOIN(",", TRUE, _xlfn.UNIQUE(IF((序时账[日期]=B34)*(序时账[凭证字号]=C34)*IF(G34=0,序时账[借方金额]<>0,序时账[借方金额]=0)*(序时账[科目编码]<>D34), 序时账[科目名称], "")))} -> 企业所得税 | K34: 企业所得税
A35: {=_xlfn.TEXTJOIN(",", TRUE, _xlfn.UNIQUE(IF((序时账[日期]=B35)*(序时账[凭证字号]=C35), 序时账[科目编码], "")))} -> 5603001,1002001 | B35: 45687 | C35: 11 | D35: 5603001 | E35: 银行手续费 | F35: 账户管理费 | G35: 200 | H35: 0 | I35: =IF(F35<>"结转本期损益",_xlfn.XLOOKUP(D35,科目余额表[科目编码],科目余额表[抽查项目],"无匹配"),"期间结转") -> 财务费用 | J35: {=_xlfn.TEXTJOIN(",", TRUE, _xlfn.UNIQUE(IF((序时账[日期]=B35)*(序时账[凭证字号]=C35)*IF(G35=0,序时账[借方金额]<>0,序时账[借方金额]=0)*(序时账[科目编码]<>D35), 序时账[科目名称], "")))} -> ABC银行账户
A36: {=_xlfn.TEXTJOIN(",", TRUE, _xlfn.UNIQUE(IF((序时账[日期]=B36)*(序时账[凭证字号]=C36), 序时账[科目编码], "")))} -> 5603001,1002001 | B36: 45687 | C36: 11 | D36: 1002001 | E36: ABC银行账户 | F36: 账户管理费 | G36: 0 | H36: 200 | I36: =IF(F36<>"结转本期损益",_xlfn.XLOOKUP(D36,科目余额表[科目编码],科目余额表[抽查项目],"无匹配"),"期间结转") -> 银行存款 | J36: {=_xlfn.TEXTJOIN(",", TRUE, _xlfn.UNIQUE(IF((序时账[日期]=B36)*(序时账[凭证字号]=C36)*IF(G36=0,序时账[借方金额]<>0,序时账[借方金额]=0)*(序时账[科目编码]<>D36), 序时账[科目名称], "")))} -> 银行手续费 | K36: 银行手续费
A37: {=_xlfn.TEXTJOIN(",", TRUE, _xlfn.UNIQUE(IF((序时账[日期]=B37)*(序时账[凭证字号]=C37), 序时账[科目编码], "")))} -> 5001,3103 | B37: 45687 | C37: 12 | D37: 5001 | E37: 主营业务收入 | F37: 结转本期损益 | G37: 1010000 | H37: 0 | I37: =IF(F37<>"结转本期损益",_xlfn.XLOOKUP(D37,科目余额表[科目编码],科目余额表[抽查项目],"无匹配"),"期间结转") -> 期间结转 | J37: {=_xlfn.TEXTJOIN(",", TRUE, _xlfn.UNIQUE(IF((序时账[日期]=B37)*(序时账[凭证字号]=C37)*IF(G37=0,序时账[借方金额]<>0,序时账[借方金额]=0)*(序时账[科目编码]<>D37), 序时账[科目名称], "")))} -> 本年利润
A38: {=_xlfn.TEXTJOIN(",", TRUE, _xlfn.UNIQUE(IF((序时账[日期]=B38)*(序时账[凭证字号]=C38), 序时账[科目编码], "")))} -> 5001,3103 | B38: 45687 | C38: 12 | D38: 3103 | E38: 本年利润 | F38: 结转本期损益 | G38: 0 | H38: 1010000 | I38: =IF(F38<>"结转本期损益",_xlfn.XLOOKUP(D38,科目余额表[科目编码],科目余额表[抽查项目],"无匹配"),"期间结转") -> 期间结转 | J38: {=_xlfn.TEXTJOIN(",", TRUE, _xlfn.UNIQUE(IF((序时账[日期]=B38)*(序时账[凭证字号]=C38)*IF(G38=0,序时账[借方金额]<>0,序时账[借方金额]=0)*(序时账[科目编码]<>D38), 序时账[科目名称], "")))} -> 主营业务收入
A39: {=_xlfn.TEXTJOIN(",", TRUE, _xlfn.UNIQUE(IF((序时账[日期]=B39)*(序时账[凭证字号]=C39), 序时账[科目编码], "")))} -> 3103,5401,5403001,5403002,5403003,5602001,5603001 | B39: 45687 | C39: 13 | D39: 3103 | E39: 本年利润 | F39: 结转本期损益 | G39: 910329.52 | H39: 0 | I39: =IF(F39<>"结转本期损益",_xlfn.XLOOKUP(D39,科目余额表[科目编码],科目余额表[抽查项目],"无匹配"),"期间结转") -> 期间结转 | J39: {=_xlfn.TEXTJOIN(",", TRUE, _xlfn.UNIQUE(IF((序时账[日期]=B39)*(序时账[凭证字号]=C39)*IF(G39=0,序时账[借方金额]<>0,序时账[借方金额]=0)*(序时账[科目编码]<>D39), 序时账[科目名称], "")))} -> 主营业务成本,城市维护建设税,教育费附加,地方教育费附加,管理费用-折旧费,银行手续费
A40: {=_xlfn.TEXTJOIN(",", TRUE, _xlfn.UNIQUE(IF((序时账[日期]=B40)*(序时账[凭证字号]=C40), 序时账[科目编码], "")))} -> 3103,5401,5403001,5403002,5403003,5602001,5603001 | B40: 45687 | C40: 13 | D40: 5401 | E40: 主营业务成本 | F40: 结转本期损益 | G40: 0 | H40: 901000 | I40: =IF(F40<>"结转本期损益",_xlfn.XLOOKUP(D40,科目余额表[科目编码],科目余额表[抽查项目],"无匹配"),"期间结转") -> 期间结转 | J40: {=_xlfn.TEXTJOIN(",", TRUE, _xlfn.UNIQUE(IF((序时账[日期]=B40)*(序时账[凭证字号]=C40)*IF(G40=0,序时账[借方金额]<>0,序时账[借方金额]=0)*(序时账[科目编码]<>D40), 序时账[科目名称], "")))} -> 本年利润
A41: {=_xlfn.TEXTJOIN(",", TRUE, _xlfn.UNIQUE(IF((序时账[日期]=B41)*(序时账[凭证字号]=C41), 序时账[科目编码], "")))} -> 3103,5401,5403001,5403002,5403003,5602001,5603001 | B41: 45687 | C41: 13 | D41: 5403001 | E41: 城市维护建设税 | F41: 结转本期损益 | G41: 0 | H41: 4724.72 | I41: =IF(F41<>"结转本期损益",_xlfn.XLOOKUP(D41,科目余额表[科目编码],科目余额表[抽查项目],"无匹配"),"期间结转") -> 期间结转 | J41: {=_xlfn.TEXTJOIN(",", TRUE, _xlfn.UNIQUE(IF((序时账[日期]=B41)*(序时账[凭证字号]=C41)*IF(G41=0,序时账[借方金额]<>0,序时账[借方金额]=0)*(序时账[科目编码]<>D41), 序时账[科目名称], "")))} -> 本年利润
A42: {=_xlfn.TEXTJOIN(",", TRUE, _xlfn.UNIQUE(IF((序时账[日期]=B42)*(序时账[凭证字号]=C42), 序时账[科目编码], "")))} -> 3103,5401,5403001,5403002,5403003,5602001,5603001 | B42: 45687 | C42: 13 | D42: 5403002 | E42: 教育费附加 | F42: 结转本期损益 | G42: 0 | H42: 2024.88 | I42: =IF(F42<>"结转本期损益",_xlfn.XLOOKUP(D42,科目余额表[科目编码],科目余额表[抽查项目],"无匹配"),"期间结转") -> 期间结转 | J42: {=_xlfn.TEXTJOIN(",", TRUE, _xlfn.UNIQUE(IF((序时账[日期]=B42)*(序时账[凭证字号]=C42)*IF(G42=0,序时账[借方金额]<>0,序时账[借方金额]=0)*(序时账[科目编码]<>D42), 序时账[科目名称], "")))} -> 本年利润
A43: {=_xlfn.TEXTJOIN(",", TRUE, _xlfn.UNIQUE(IF((序时账[日期]=B43)*(序时账[凭证字号]=C43), 序时账[科目编码], "")))} -> 3103,5401,5403001,5403002,5403003,5602001,5603001 | B43: 45687 | C43: 13 | D43: 5403003 | E43: 地方教育费附加 | F43: 结转本期损益 | G43: 0 | H43: 1349.92 | I43: =IF(F43<>"结转本期损益",_xlfn.XLOOKUP(D43,科目余额表[科目编码],科目余额表[抽查项目],"无匹配"),"期间结转") -> 期间结转 | J43: {=_xlfn.TEXTJOIN(",", TRUE, _xlfn.UNIQUE(IF((序时账[日期]=B43)*(序时账[凭证字号]=C43)*IF(G43=0,序时账[借方金额]<>0,序时账[借方金额]=0)*(序时账[科目编码]<>D43), 序时账[科目名称], "")))} -> 本年利润
A44: {=_xlfn.TEXTJOIN(",", TRUE, _xlfn.UNIQUE(IF((序时账[日期]=B44)*(序时账[凭证字号]=C44), 序时账[科目编码], "")))} -> 3103,5401,5403001,5403002,5403003,5602001,5603001 | B44: 45687 | C44: 13 | D44: 5602001 | E44: 管理费用-折旧费 | F44: 结转本期损益 | G44: 0 | H44: 1030 | I44: =IF(F44<>"结转本期损益",_xlfn.XLOOKUP(D44,科目余额表[科目编码],科目余额表[抽查项目],"无匹配"),"期间结转") -> 期间结转 | J44: {=_xlfn.TEXTJOIN(",", TRUE, _xlfn.UNIQUE(IF((序时账[日期]=B44)*(序时账[凭证字号]=C44)*IF(G44=0,序时账[借方金额]<>0,序时账[借方金额]=0)*(序时账[科目编码]<>D44), 序时账[科目名称], "")))} -> 本年利润
...

Sheet 试算平衡表
A1: 数据类别 | B1: 报表项目 | C1: 期初金额 | D1: 审定报表金额 | E1: 调整金额 | F1: 未申报表金额 | G1: 数据比对差额
A2: 借 | B2: 货币资金 | C2: 1010837.3 | D2: =IF(A2="借",SUMIF(科目余额表[已审报表项目],B2,科目余额表[期末借方])-SUMIF(科目余额表[已审报表项目],B2,科目余额表[期末贷方]),IF(A2="贷",SUMIF(科目余额表[已审报表项目],B2,科目余额表[期末贷方])-SUMIF(科目余额表[已审报表项目],B2,科目余额表[期末借方]),SUMIF(科目余额表[已审报表项目],B2,科目余额表[本期借方]))) -> 14462935 | E2: =试算平衡表[[#This Row],[审定报表金额]]-试算平衡表[[#This Row],[未申报表金额]] -> -0.0099999998 | F2: 14462935 | G2: =F2-IF(A2="借",SUMIF(科目余额表[未审报表项目],B2,科目余额表[期末借方])-SUMIF(科目余额表[未审报表项目],B2,科目余额表[期末贷方]),IF(A2="贷",SUMIF(科目余额表[未审报表项目],B2,科目余额表[期末贷方])-SUMIF(科目余额表[未审报表项目],B2,科目余额表[期末借方]),SUMIF(科目余额表[未审报表项目],B2,科目余额表[本期借方]))) -> 0.0099999998
A3: 借 | B3: 交易性金融资产 | C3: 0 | D3: =IF(A3="借",SUMIF(科目余额表[已审报表项目],B3,科目余额表[期末借方])-SUMIF(科目余额表[已审报表项目],B3,科目余额表[期末贷方]),IF(A3="贷",SUMIF(科目余额表[已审报表项目],B3,科目余额表[期末贷方])-SUMIF(科目余额表[已审报表项目],B3,科目余额表[期末借方]),SUMIF(科目余额表[已审报表项目],B3,科目余额表[本期借方]))) -> 0 | E3: =试算平衡表[[#This Row],[审定报表金额]]-试算平衡表[[#This Row],[未申报表金额]] -> 0 | F3: 0 | G3: =F3-IF(A3="借",SUMIF(科目余额表[未审报表项目],B3,科目余额表[期末借方])-SUMIF(科目余额表[未审报表项目],B3,科目余额表[期末贷方]),IF(A3="贷",SUMIF(科目余额表[未审报表项目],B3,科目余额表[期末贷方])-SUMIF(科目余额表[未审报表项目],B3,科目余额表[期末借方]),SUMIF(科目余额表[未审报表项目],B3,科目余额表[本期借方]))) -> 0
A4: 借 | B4: 衍生金融资产 | C4: 0 | D4: =IF(A4="借",SUMIF(科目余额表[已审报表项目],B4,科目余额表[期末借方])-SUMIF(科目余额表[已审报表项目],B4,科目余额表[期末贷方]),IF(A4="贷",SUMIF(科目余额表[已审报表项目],B4,科目余额表[期末贷方])-SUMIF(科目余额表[已审报表项目],B4,科目余额表[期末借方]),SUMIF(科目余额表[已审报表项目],B4,科目余额表[本期借方]))) -> 0 | E4: =试算平衡表[[#This Row],[审定报表金额]]-试算平衡表[[#This Row],[未申报表金额]] -> 0 | F4: 0 | G4: =F4-IF(A4="借",SUMIF(科目余额表[未审报表项目],B4,科目余额表[期末借方])-SUMIF(科目余额表[未审报表项目],B4,科目余额表[期末贷方]),IF(A4="贷",SUMIF(科目余额表[未审报表项目],B4,科目余额表[期末贷方])-SUMIF(科目余额表[未审报表项目],B4,科目余额表[期末借方]),SUMIF(科目余额表[未审报表项目],B4,科目余额表[本期借方]))) -> 0
A5: 借 | B5: 应收票据 | C5: 0 | D5: =IF(A5="借",SUMIF(科目余额表[已审报表项目],B5,科目余额表[期末借方])-SUMIF(科目余额表[已审报表项目],B5,科目余额表[期末贷方]),IF(A5="贷",SUMIF(科目余额表[已审报表项目],B5,科目余额表[期末贷方])-SUMIF(科目余额表[已审报表项目],B5,科目余额表[期末借方]),SUMIF(科目余额表[已审报表项目],B5,科目余额表[本期借方]))) -> 0 | E5: =试算平衡表[[#This Row],[审定报表金额]]-试算平衡表[[#This Row],[未申报表金额]] -> 0 | F5: 0 | G5: =F5-IF(A5="借",SUMIF(科目余额表[未审报表项目],B5,科目余额表[期末借方])-SUMIF(科目余额表[未审报表项目],B5,科目余额表[期末贷方]),IF(A5="贷",SUMIF(科目余额表[未审报表项目],B5,科目余额表[期末贷方])-SUMIF(科目余额表[未审报表项目],B5,科目余额表[期末借方]),SUMIF(科目余额表[未审报表项目],B5,科目余额表[本期借方]))) -> 0
A6: 借 | B6: 应收账款 | C6: 5547848 | D6: =IF(A6="借",SUMIF(科目余额表[已审报表项目],B6,科目余额表[期末借方])-SUMIF(科目余额表[已审报表项目],B6,科目余额表[期末贷方]),IF(A6="贷",SUMIF(科目余额表[已审报表项目],B6,科目余额表[期末贷方])-SUMIF(科目余额表[已审报表项目],B6,科目余额表[期末借方]),SUMIF(科目余额表[已审报表项目],B6,科目余额表[本期借方]))) -> 8165248 | E6: =试算平衡表[[#This Row],[审定报表金额]]-试算平衡表[[#This Row],[未申报表金额]] -> 0 | F6: 8165248 | G6: =F6-IF(A6="借",SUMIF(科目余额表[未审报表项目],B6,科目余额表[期末借方])-SUMIF(科目余额表[未审报表项目],B6,科目余额表[期末贷方]),IF(A6="贷",SUMIF(科目余额表[未审报表项目],B6,科目余额表[期末贷方])-SUMIF(科目余额表[未审报表项目],B6,科目余额表[期末借方]),SUMIF(科目余额表[未审报表项目],B6,科目余额表[本期借方]))) -> 0
A7: 借 | B7: 应收款项融资 | C7: 0 | D7: =IF(A7="借",SUMIF(科目余额表[已审报表项目],B7,科目余额表[期末借方])-SUMIF(科目余额表[已审报表项目],B7,科目余额表[期末贷方]),IF(A7="贷",SUMIF(科目余额表[已审报表项目],B7,科目余额表[期末贷方])-SUMIF(科目余额表[已审报表项目],B7,科目余额表[期末借方]),SUMIF(科目余额表[已审报表项目],B7,科目余额表[本期借方]))) -> 0 | E7: =试算平衡表[[#This Row],[审定报表金额]]-试算平衡表[[#This Row],[未申报表金额]] -> 0 | F7: 0 | G7: =F7-IF(A7="借",SUMIF(科目余额表[未审报表项目],B7,科目余额表[期末借方])-SUMIF(科目余额表[未审报表项目],B7,科目余额表[期末贷方]),IF(A7="贷",SUMIF(科目余额表[未审报表项目],B7,科目余额表[期末贷方])-SUMIF(科目余额表[未审报表项目],B7,科目余额表[期末借方]),SUMIF(科目余额表[未审报表项目],B7,科目余额表[本期借方]))) -> 0
A8: 借 | B8: 预付款项 | C8: 2001987.2 | D8: =IF(A8="借",SUMIF(科目余额表[已审报表项目],B8,科目余额表[期末借方])-SUMIF(科目余额表[已审报表项目],B8,科目余额表[期末贷方]),IF(A8="贷",SUMIF(科目余额表[已审报表项目],B8,科目余额表[期末贷方])-SUMIF(科目余额表[已审报表项目],B8,科目余额表[期末借方]),SUMIF(科目余额表[已审报表项目],B8,科目余额表[本期借方]))) -> 730048.34 | E8: =试算平衡表[[#This Row],[审定报表金额]]-试算平衡表[[#This Row],[未申报表金额]] -> 3057325.1 | F8: -2327276.8 | G8: =F8-IF(A8="借",SUMIF(科目余额表[未审报表项目],B8,科目余额表[期末借方])-SUMIF(科目余额表[未审报表项目],B8,科目余额表[期末贷方]),IF(A8="贷",SUMIF(科目余额表[未审报表项目],B8,科目余额表[期末贷方])-SUMIF(科目余额表[未审报表项目],B8,科目余额表[期末借方]),SUMIF(科目余额表[未审报表项目],B8,科目余额表[本期借方]))) -> 0
A9: 借 | B9: 其他应收款 | C9: 229934.57 | D9: =IF(A9="借",SUMIF(科目余额表[已审报表项目],B9,科目余额表[期末借方])-SUMIF(科目余额表[已审报表项目],B9,科目余额表[期末贷方]),IF(A9="贷",SUMIF(科目余额表[已审报表项目],B9,科目余额表[期末贷方])-SUMIF(科目余额表[已审报表项目],B9,科目余额表[期末借方]),SUMIF(科目余额表[已审报表项目],B9,科目余额表[本期借方]))) -> 219934.57 | E9: =试算平衡表[[#This Row],[审定报表金额]]-试算平衡表[[#This Row],[未申报表金额]] -> 0 | F9: 219934.57 | G9: =F9-IF(A9="借",SUMIF(科目余额表[未审报表项目],B9,科目余额表[期末借方])-SUMIF(科目余额表[未审报表项目],B9,科目余额表[期末贷方]),IF(A9="贷",SUMIF(科目余额表[未审报表项目],B9,科目余额表[期末贷方])-SUMIF(科目余额表[未审报表项目],B9,科目余额表[期末借方]),SUMIF(科目余额表[未审报表项目],B9,科目余额表[本期借方]))) -> 0
A10: 借 | B10: 存货 | C10: 9987654.7 | D10: =IF(A10="借",SUMIF(科目余额表[已审报表项目],B10,科目余额表[期末借方])-SUMIF(科目余额表[已审报表项目],B10,科目余额表[期末贷方]),IF(A10="贷",SUMIF(科目余额表[已审报表项目],B10,科目余额表[期末贷方])-SUMIF(科目余额表[已审报表项目],B10,科目余额表[期末借方]),SUMIF(科目余额表[已审报表项目],B10,科目余额表[本期借方]))) -> 7655954.7 | E10: =试算平衡表[[#This Row],[审定报表金额]]-试算平衡表[[#This Row],[未申报表金额]] -> 0 | F10: 7655954.7 | G10: =F10-IF(A10="借",SUMIF(科目余额表[未审报表项目],B10,科目余额表[期末借方])-SUMIF(科目余额表[未审报表项目],B10,科目余额表[期末贷方]),IF(A10="贷",SUMIF(科目余额表[未审报表项目],B10,科目余额表[期末贷方])-SUMIF(科目余额表[未审报表项目],B10,科目余额表[期末借方]),SUMIF(科目余额表[未审报表项目],B10,科目余额表[本期借方]))) -> 0
A11: 借 | B11: 合同资产 | C11: 0 | D11: =IF(A11="借",SUMIF(科目余额表[已审报表项目],B11,科目余额表[期末借方])-SUMIF(科目余额表[已审报表项目],B11,科目余额表[期末贷方]),IF(A11="贷",SUMIF(科目余额表[已审报表项目],B11,科目余额表[期末贷方])-SUMIF(科目余额表[已审报表项目],B11,科目余额表[期末借方]),SUMIF(科目余额表[已审报表项目],B11,科目余额表[本期借方]))) -> 0 | E11: =试算平衡表[[#This Row],[审定报表金额]]-试算平衡表[[#This Row],[未申报表金额]] -> 0 | F11: 0 | G11: =F11-IF(A11="借",SUMIF(科目余额表[未审报表项目],B11,科目余额表[期末借方])-SUMIF(科目余额表[未审报表项目],B11,科目余额表[期末贷方]),IF(A11="贷",SUMIF(科目余额表[未审报表项目],B11,科目余额表[期末贷方])-SUMIF(科目余额表[未审报表项目],B11,科目余额表[期末借方]),SUMIF(科目余额表[未审报表项目],B11,科目余额表[本期借方]))) -> 0
A12: 借 | B12: 持有待售资产 | C12: 0 | D12: =IF(A12="借",SUMIF(科目余额表[已审报表项目],B12,科目余额表[期末借方])-SUMIF(科目余额表[已审报表项目],B12,科目余额表[期末贷方]),IF(A12="贷",SUMIF(科目余额表[已审报表项目],B12,科目余额表[期末贷方])-SUMIF(科目余额表[已审报表项目],B12,科目余额表[期末借方]),SUMIF(科目余额表[已审报表项目],B12,科目余额表[本期借方]))) -> 0 | E12: =试算平衡表[[#This Row],[审定报表金额]]-试算平衡表[[#This Row],[未申报表金额]] -> 0 | F12: 0 | G12: =F12-IF(A12="借",SUMIF(科目余额表[未审报表项目],B12,科目余额表[期末借方])-SUMIF(科目余额表[未审报表项目],B12,科目余额表[期末贷方]),IF(A12="贷",SUMIF(科目余额表[未审报表项目],B12,科目余额表[期末贷方])-SUMIF(科目余额表[未审报表项目],B12,科目余额表[期末借方]),SUMIF(科目余额表[未审报表项目],B12,科目余额表[本期借方]))) -> 0
A13: 借 | B13: 一年内到期的非流动资产 | C13: 0 | D13: =IF(A13="借",SUMIF(科目余额表[已审报表项目],B13,科目余额表[期末借方])-SUMIF(科目余额表[已审报表项目],B13,科目余额表[期末贷方]),IF(A13="贷",SUMIF(科目余额表[已审报表项目],B13,科目余额表[期末贷方])-SUMIF(科目余额表[已审报表项目],B13,科目余额表[期末借方]),SUMIF(科目余额表[已审报表项目],B13,科目余额表[本期借方]))) -> 0 | E13: =试算平衡表[[#This Row],[审定报表金额]]-试算平衡表[[#This Row],[未申报表金额]] -> 0 | F13: 0 | G13: =F13-IF(A13="借",SUMIF(科目余额表[未审报表项目],B13,科目余额表[期末借方])-SUMIF(科目余额表[未审报表项目],B13,科目余额表[期末贷方]),IF(A13="贷",SUMIF(科目余额表[未审报表项目],B13,科目余额表[期末贷方])-SUMIF(科目余额表[未审报表项目],B13,科目余额表[期末借方]),SUMIF(科目余额表[未审报表项目],B13,科目余额表[本期借方]))) -> 0
... A79: 发生 | B79: 所得税费用 | C79: 0 | D79: =IF(A79="借",SUMIF(科目余额表[已审报表项目],B79,科目余额表[期末借方])-SUMIF(科目余额表[已审报表项目],B79,科目余额表[期末贷方]),IF(A79="贷",SUMIF(科目余额表[已审报表项目],B79,科目余额表[期末贷方])-SUMIF(科目余额表[已审报表项目],B79,科目余额表[期末借方]),SUMIF(科目余额表[已审报表项目],B79,科目余额表[本期借方]))) -> 579779.36 | E79: =试算平衡表[[#This Row],[审定报表金额]]-试算平衡表[[#This Row],[未申报表金额]] -> 0 | F79: 579779.36 | G79: =F79-IF(A79="借",SUMIF(科目余额表[未审报表项目],B79,科目余额表[期末借方])-SUMIF(科目余额表[未审报表项目],B79,科目余额表[期末贷方]),IF(A79="贷",SUMIF(科目余额表[未审报表项目],B79,科目余额表[期末贷方])-SUMIF(科目余额表[未审报表项目],B79,科目余额表[期末借方]),SUMIF(科目余额表[未审报表项目],B79,科目余额表[本期借方]))) -> 0

Sheet 调整目录
A1: 科目编码 | B1: 科目名称 | C1: 期初借方 | D1: 期初贷方 | E1: 本期借方 | F1: 本期贷方 | G1: 期末借方 | H1: 期末贷方 | I1: 未审报表项目 | J1: 已审报表项目 | K1: 调整 | L1: 抽查项目 | M1: 测算项目
A2: {=_xlfn._xlws.FILTER(科目余额表!A:M,科目余额表!K:K="是")} -> 1123001 | B2: K有限公司 | C2: 200199.49 | D2: 0 | E2: 0 | F2: 568842 | G2: -368642.51 | H2: 0 | I2: 预付款项 | J2: 应付账款 | K2: 是 | L2: 预付款项 | M2: 0
A3: 1123002 | B3: L有限公司 | C3: 188355.45 | D3: 0 | E3: 0 | F3: 698000 | G3: -509644.55 | H3: 0 | I3: 预付款项 | J3: 应付账款 | K3: 是 | L3: 预付款项 | M3: 0
A4: 1123003 | B4: M有限公司 | C4: 422009.32 | D4: 0 | E4: 0 | F4: 568842 | G4: -146832.68 | H4: 0 | I4: 预付款项 | J4: 应付账款 | K4: 是 | L4: 预付款项 | M4: 0
A5: 1123005 | B5: C有限公司 | C5: 235333.35 | D5: 0 | E5: 0 | F5: 1361700 | G5: -1126366.6 | H5: 0 | I5: 预付款项 | J5: 应付账款 | K5: 是 | L5: 预付款项 | M5: 0
A6: 1123007 | B6: P有限公司 | C6: 230444.39 | D6: 0 | E6: 0 | F6: 763880 | G6: -533435.61 | H6: 0 | I6: 预付款项 | J6: 应付账款 | K6: 是 | L6: 预付款项 | M6: 0
A7: 1123008 | B7: Q有限公司 | C7: 201008 | D7: 0 | E7: 0 | F7: 908000 | G7: -706992 | H7: 0 | I7: 预付款项 | J7: 应付账款 | K7: 是 | L7: 预付款项 | M7: 0
A8: 5401 | B8: 主营业务成本 | C8: 0 | D8: 0 | E8: 10878000 | F8: 10878000 | G8: 0 | H8: 0 | I8: 营业成本 | J8: 0 | K8: 是 | L8: 营业成本 | M8: 0
A9: 5602002 | B9: 办公费 | C9: 0 | D9: 0 | E9: 5275 | F9: 5275 | G9: 0 | H9: 0 | I9: 管理费用 | J9: 0 | K9: 是 | L9: 管理费用 | M9: 0
A10: 0 | B10: N有限公司 | C10: 0 | D10: 0 | E10: 0 | F10: 0 | G10: -334588.9 | H10: 0 | I10: 0 | J10: 预付款项 | K10: 是 | L10: 0 | M10: 0
A11: 0 | B11: N有限公司 | C11: 0 | D11: 0 | E11: 0 | F11: 0 | G11: 0 | H11: -334588.9 | I11: 0 | J11: 应付账款 | K11: 是 | L11: 0 | M11: 0
A12: 0 | B12: 主营业务成本 | C12: 0 | D12: 0 | E12: 10789000 | F12: 10789000 | G12: 0 | H12: 0 | I12: 0 | J12: 营业成本 | K12: 是 | L12: 0 | M12: 0
A13: 0 | B13: 研发费用-直接投入 | C13: 0 | D13: 0 | E13: 89000 | F13: 89000 | G13: 0 | H13: 0 | I13: 0 | J13: 研发费用 | K13: 是 | L13: 0 | M13: 0
A14: 0 | B14: 管理费用-办公费 | C14: 0 | D14: 0 | E14: 5175 | F14: 5175 | G14: 0 | H14: 0 | I14: 0 | J14: 管理费用 | K14: 是 | L14: 0 | M14: 0
A15: 0 | B15: 研发费用-办公费 | C15: 0 | D15: 0 | E15: 100 | F15: 100 | G15: 0 | H15: 0 | I15: 0 | J15: 研发费用 | K15: 是 | L15: 0 | M15: 0

Sheet 附注自动计算
A1: 货币资金
A2: 项目 | B2: 年末余额 | C2: 年初余额
A3: 现金 | B3: =SUMIF(科目余额表[测算项目],A3,科目余额表[期末借方]) -> 14952.34 | C3: =SUMIF(科目余额表[测算项目],A3,科目余额表[期初借方]) -> 15002.34
A4: 银行存款 | B4: =SUMIF(科目余额表[测算项目],A4,科目余额表[期末借方]) -> 14447983 | C4: =SUMIF(科目余额表[测算项目],A4,科目余额表[期初借方]) -> 995835
A5: 其他货币资金 | B5: =SUMIF(科目余额表[测算项目],A5,科目余额表[期末借方]) -> 0 | C5: =SUMIF(科目余额表[测算项目],A5,科目余额表[期初借方]) -> 0
A6: 合计 | B6: =SUM(B3:B5) -> 14462935 | C6: =SUM(C3:C5) -> 1010837.3
A7: 报表金额 | B7: =试算平衡表!D2 -> 14462935 | C7: =试算平衡表!C2 -> 1010837.3
A8: 差额 | B8: =B6-B7 -> 0 | C8: =C6-C7 -> 0
A9: 应收账款账龄
A10: 测算账龄 | B10: 年末余额
A11: 估算：1年以内（含1年） | B11: =SUM(往来项目数据聚合!I:I) -> 8036047.1
A12: 估算：1年以上 | B12: =SUM(往来项目数据聚合!J:J) -> 129200.88
A13: 账龄 | B13: 年末余额 | C13: 年初余额
A14: 1年以内（含1年）
A15: 1-2年（含2年） | D15: =IF(B15>C14,"年末1-2年（含2年）大于年初1年以内（含1年）","-") -> -
A16: 2-3年（含3年） | D16: =IF(B16>C15,"年末2-3年（含3年）大于年初1-2年（含2年）","-") -> -
A17: 3年以上 | D17: =IF(B17>C16,"年末3年以上大于年初2-3年（含3年）","-") -> -
A18: 小计 | B18: =SUM(B14:B17) -> 0 | C18: =SUM(C14:C17) -> 0
A19: 减：还账准备
A20: 合计 | B20: =B18-B19 -> 0 | C20: =C18-C19 -> 0
A21: 报表金额 | B21: =试算平衡表!D6 -> 8165248 | C21: =试算平衡表!C6 -> 5547848
A22: 差额 | B22: =B20-B21 -> -8165248 | C22: =C20-C21 -> -5547848
A23: 应收账款前五位
A24: 项目 | B24: 年末余额 | C24: 项目是否有重复项 | D24: 金额是否有重复项 | E24: 排序
A25: =IF(B25<>0,_xlfn.XLOOKUP(B25,往来项目数据聚合!CE:CE,往来项目数据聚合!CD:CD),0) -> F有限公司 | B25: =LARGE(往来项目数据聚合!CE:CE,E25) -> 1327000.9 | C25: =IF(COUNTIF(往来项目数据聚合!CD:CD,A25)>1,"有","-") -> - | D25: =IF(COUNTIF(往来项目数据聚合!CE:CE,B25)>1,"有","-") -> - | E25: 1
A26: =IF(B26<>0,_xlfn.XLOOKUP(B26,往来项目数据聚合!CE:CE,往来项目数据聚合!CD:CD),0) -> H有限公司 | B26: =LARGE(往来项目数据聚合!CE:CE,E26) -> 1005855.3 | C26: =IF(COUNTIF(往来项目数据聚合!CD:CD,A26)>1,"有","-") -> - | D26: =IF(COUNTIF(往来项目数据聚合!CE:CE,B26)>1,"有","-") -> - | E26: 2
A27: =IF(B27<>0,_xlfn.XLOOKUP(B27,往来项目数据聚合!CE:CE,往来项目数据聚合!CD:CD),0) -> A有限公司 | B27: =LARGE(往来项目数据聚合!CE:CE,E27) -> 918044.45 | C27: =IF(COUNTIF(往来项目数据聚合!CD:CD,A27)>1,"有","-") -> - | D27: =IF(COUNTIF(往来项目数据聚合!CE:CE,B27)>1,"有","-") -> - | E27: 3
A28: =IF(B28<>0,_xlfn.XLOOKUP(B28,往来项目数据聚合!CE:CE,往来项目数据聚合!CD:CD),0) -> I有限公司 | B28: =LARGE(往来项目数据聚合!CE:CE,E28) -> 917929.43 | C28: =IF(COUNTIF(往来项目数据聚合!CD:CD,A28)>1,"有","-") -> - | D28: =IF(COUNTIF(往来项目数据聚合!CE:CE,B28)>1,"有","-") -> - | E28: 4
A29: =IF(B29<>0,_xlfn.XLOOKUP(B29,往来项目数据聚合!CE:CE,往来项目数据聚合!CD:CD),0) -> G有限公司 | B29: =LARGE(往来项目数据聚合!CE:CE,E29) -> 849155.23 | C29: =IF(COUNTIF(往来项目数据聚合!CD:CD,A29)>1,"有","-") -> - | D29: =IF(COUNTIF(往来项目数据聚合!CE:CE,B29)>1,"有","-") -> - | E29: 5
A30: 预付款项账龄
A31: 测算账龄 | B31: 年末余额
A32: 估算：1年以内（含1年） | B32: =SUM(往来项目数据聚合!S:S) -> 205411.1
A33: 估算：1年以上 | B33: =SUM(往来项目数据聚合!T:T) -> 524637.24
A34: 账龄 | B34: 年末余额 | C34: 年初余额
A35: 1年以内（含1年）
A36: 1-2年（含2年） | D36: =IF(B36>C35,"年末1-2年（含2年）大于年初1年以内（含1年）","-") -> -
A37: 2-3年（含3年） | D37: =IF(B37>C36,"年末2-3年（含3年）大于年初1-2年（含2年）","-") -> -
A38: 3年以上 | D38: =IF(B38>C37,"年末3年以上大于年初2-3年（含3年）","-") -> -
A39: 小计 | B39: =SUM(B35:B38) -> 0 | C39: =SUM(C35:C38) -> 0
A40: 减：还账准备
...

Sheet 附注自动列示
A1: 报表项目 | B1: 存货 | G1: 科目编码 | H1: 项目 | I1: 期初借方 | J1: 期初贷方 | K1: 本期借方 | L1: 本期贷方 | M1: 期末借方 | N1: 期末贷方
A2: 试算平衡表金额 | B2: =_xlfn.XLOOKUP(B1,试算平衡表[报表项目],试算平衡表[审定报表金额],0) -> 7655954.7 | C2: =_xlfn.XLOOKUP(B1,试算平衡表[报表项目],试算平衡表[期初金额],0) -> 9987654.7 | D2: =_xlfn.XLOOKUP(B1,试算平衡表[报表项目],试算平衡表[审定报表金额],0) -> 7655954.7 | E2: =_xlfn.XLOOKUP(B1,试算平衡表[报表项目],试算平衡表[审定报表金额],0) -> 7655954.7 | G2: {=_xlfn._xlws.FILTER(科目余额表[[科目编码]:[期末贷方]],科目余额表[已审报表项目]=B1,0)} -> 1405001 | H2: R商品 | I2: 4590388.5 | J2: 0 | K2: 5826500 | L2: 5436000 | M2: 4980888.5 | N2: 0
A3: 列示金额合计 | B3: =SUM(B5:B254) -> 7655954.7 | C3: =SUM(C5:C254) -> 9987654.7 | D3: =SUM(D5:D254) -> 8546300 | E3: =SUM(E5:E254) -> 10878000 | G3: 1405002 | H3: S商品 | I3: 5397266.2 | J3: 0 | K3: 2719800 | L3: 5442000 | M3: 2675066.2 | N3: 0
A4: {=_xlfn.UNIQUE(H:H)} -> 项目 | B4: 年末余额 | C4: 年初余额 | D4: 借方发生额 | E4: 贷方发生额
A5: R商品 | B5: =ABS(SUMIF(H:H,A5,M:M)-SUMIF(H:H,A5,N:N)) -> 4980888.5 | C5: =ABS(SUMIF(H:H,A5,I:I)-SUMIF(H:H,A5,J:J)) -> 4590388.5 | D5: =SUMIF(H:H,A5,K:K) -> 5826500 | E5: =SUMIF(H:H,A5,L:L) -> 5436000
A6: S商品 | B6: =ABS(SUMIF(H:H,A6,M:M)-SUMIF(H:H,A6,N:N)) -> 2675066.2 | C6: =ABS(SUMIF(H:H,A6,I:I)-SUMIF(H:H,A6,J:J)) -> 5397266.2 | D6: =SUMIF(H:H,A6,K:K) -> 2719800 | E6: =SUMIF(H:H,A6,L:L) -> 5442000
A7: 0 | B7: =ABS(SUMIF(H:H,A7,M:M)-SUMIF(H:H,A7,N:N)) -> 0 | C7: =ABS(SUMIF(H:H,A7,I:I)-SUMIF(H:H,A7,J:J)) -> 0 | D7: =SUMIF(H:H,A7,K:K) -> 0 | E7: =SUMIF(H:H,A7,L:L) -> 0
B8: =ABS(SUMIF(H:H,A8,M:M)-SUMIF(H:H,A8,N:N)) -> 0 | C8: =ABS(SUMIF(H:H,A8,I:I)-SUMIF(H:H,A8,J:J)) -> 0 | D8: =SUMIF(H:H,A8,K:K) -> 0 | E8: =SUMIF(H:H,A8,L:L) -> 0
B9: =ABS(SUMIF(H:H,A9,M:M)-SUMIF(H:H,A9,N:N)) -> 0 | C9: =ABS(SUMIF(H:H,A9,I:I)-SUMIF(H:H,A9,J:J)) -> 0 | D9: =SUMIF(H:H,A9,K:K) -> 0 | E9: =SUMIF(H:H,A9,L:L) -> 0
B10: =ABS(SUMIF(H:H,A10,M:M)-SUMIF(H:H,A10,N:N)) -> 0 | C10: =ABS(SUMIF(H:H,A10,I:I)-SUMIF(H:H,A10,J:J)) -> 0 | D10: =SUMIF(H:H,A10,K:K) -> 0 | E10: =SUMIF(H:H,A10,L:L) -> 0
B11: =ABS(SUMIF(H:H,A11,M:M)-SUMIF(H:H,A11,N:N)) -> 0 | C11: =ABS(SUMIF(H:H,A11,I:I)-SUMIF(H:H,A11,J:J)) -> 0 | D11: =SUMIF(H:H,A11,K:K) -> 0 | E11: =SUMIF(H:H,A11,L:L) -> 0
B12: =ABS(SUMIF(H:H,A12,M:M)-SUMIF(H:H,A12,N:N)) -> 0 | C12: =ABS(SUMIF(H:H,A12,I:I)-SUMIF(H:H,A12,J:J)) -> 0 | D12: =SUMIF(H:H,A12,K:K) -> 0 | E12: =SUMIF(H:H,A12,L:L) -> 0
B13: =ABS(SUMIF(H:H,A13,M:M)-SUMIF(H:H,A13,N:N)) -> 0 | C13: =ABS(SUMIF(H:H,A13,I:I)-SUMIF(H:H,A13,J:J)) -> 0 | D13: =SUMIF(H:H,A13,K:K) -> 0 | E13: =SUMIF(H:H,A13,L:L) -> 0
B14: =ABS(SUMIF(H:H,A14,M:M)-SUMIF(H:H,A14,N:N)) -> 0 | C14: =ABS(SUMIF(H:H,A14,I:I)-SUMIF(H:H,A14,J:J)) -> 0 | D14: =SUMIF(H:H,A14,K:K) -> 0 | E14: =SUMIF(H:H,A14,L:L) -> 0
B15: =ABS(SUMIF(H:H,A15,M:M)-SUMIF(H:H,A15,N:N)) -> 0 | C15: =ABS(SUMIF(H:H,A15,I:I)-SUMIF(H:H,A15,J:J)) -> 0 | D15: =SUMIF(H:H,A15,K:K) -> 0 | E15: =SUMIF(H:H,A15,L:L) -> 0
B16: =ABS(SUMIF(H:H,A16,M:M)-SUMIF(H:H,A16,N:N)) -> 0 | C16: =ABS(SUMIF(H:H,A16,I:I)-SUMIF(H:H,A16,J:J)) -> 0 | D16: =SUMIF(H:H,A16,K:K) -> 0 | E16: =SUMIF(H:H,A16,L:L) -> 0
B17: =ABS(SUMIF(H:H,A17,M:M)-SUMIF(H:H,A17,N:N)) -> 0 | C17: =ABS(SUMIF(H:H,A17,I:I)-SUMIF(H:H,A17,J:J)) -> 0 | D17: =SUMIF(H:H,A17,K:K) -> 0 | E17: =SUMIF(H:H,A17,L:L) -> 0
B18: =ABS(SUMIF(H:H,A18,M:M)-SUMIF(H:H,A18,N:N)) -> 0 | C18: =ABS(SUMIF(H:H,A18,I:I)-SUMIF(H:H,A18,J:J)) -> 0 | D18: =SUMIF(H:H,A18,K:K) -> 0 | E18: =SUMIF(H:H,A18,L:L) -> 0
B19: =ABS(SUMIF(H:H,A19,M:M)-SUMIF(H:H,A19,N:N)) -> 0 | C19: =ABS(SUMIF(H:H,A19,I:I)-SUMIF(H:H,A19,J:J)) -> 0 | D19: =SUMIF(H:H,A19,K:K) -> 0 | E19: =SUMIF(H:H,A19,L:L) -> 0
... B254: =ABS(SUMIF(H:H,A254,M:M)-SUMIF(H:H,A254,N:N)) -> 0 | C254: =ABS(SUMIF(H:H,A254,I:I)-SUMIF(H:H,A254,J:J)) -> 0 | D254: =SUMIF(H:H,A254,K:K) -> 0 | E254: =SUMIF(H:H,A254,L:L) -> 0

Sheet 往来抵消检查
A1: 项目 | B1: 循环重复 | C1: 总重复 | E1: 票据是否双向 | F1: 收款是否双向 | G1: 付款是否双向 | H1: 合同是否双向 | I1: 其他是否双向 | K1: 应收票据 | L1: 应付票据 | M1: 应收账款 | N1: 预收款项 | O1: 预付款项 | P1: 应付账款 | Q1: 合同资产 | R1: 合同负债 | S1: 其他应收款 | T1: 其他应付款 | V1: {=_xlfn._xlws.FILTER(科目余额表[科目名称],科目余额表[未审报表项目]="应收票据")} -> #VALUE! | W1: {=_xlfn._xlws.FILTER(科目余额表[科目名称],科目余额表[未审报表项目]="应收账款")} -> A有限公司 | X1: {=_xlfn._xlws.FILTER(科目余额表[科目名称],科目余额表[未审报表项目]="预付款项")} -> K有限公司 | Y1: {=_xlfn._xlws.FILTER(科目余额表[科目名称],科目余额表[未审报表项目]="合同资产")} -> #VALUE! | Z1: {=_xlfn._xlws.FILTER(科目余额表[科目名称],科目余额表[未审报表项目]="其他应收款")} -> 张三 | AA1: {=_xlfn._xlws.FILTER(科目余额表[科目名称],科目余额表[未审报表项目]="应付票据")} -> #VALUE! | AB1: {=_xlfn._xlws.FILTER(科目余额表[科目名称],科目余额表[未审报表项目]="应付账款")} -> T有限公司 | AC1: {=_xlfn._xlws.FILTER(科目余额表[科目名称],科目余额表[未审报表项目]="预收款项")} -> #VALUE! | AD1: {=_xlfn._xlws.FILTER(科目余额表[科目名称],科目余额表[未审报表项目]="合同资产")} -> #VALUE! | AE1: {=_xlfn._xlws.FILTER(科目余额表[科目名称],科目余额表[未审报表项目]="其他应付款")} -> 甲
A2: {=_xlfn.UNIQUE(_xlfn.TOCOL(V:AE,3,TRUE))} -> A有限公司 | B2: =IF(COUNTIF(E2:I2,"是")>0,"是","—") -> — | C2: =IF(10-COUNTIF(K2:T2,0)>1,"是","—") -> — | E2: =IF(AND(K2<>0,L2<>0),"是","—") -> — | F2: =IF(AND(M2<>0,N2<>0),"是","—") -> — | G2: =IF(AND(O2<>0,P2<>0),"是","—") -> — | H2: =IF(AND(Q2<>0,R2<>0),"是","—") -> — | I2: =IF(AND(S2<>0,T2<>0),"是","—") -> — | K2: =SUMIFS(科目余额表[期末借方],科目余额表[已审报表项目],K$1,科目余额表[科目名称],A2)-SUMIFS(科目余额表[期末贷方],科目余额表[已审报表项目],K$1,科目余额表[科目名称],A2) -> 0 | L2: =SUMIFS(科目余额表[期末贷方],科目余额表[已审报表项目],L$1,科目余额表[科目名称],A2)-SUMIFS(科目余额表[期末借方],科目余额表[已审报表项目],L$1,科目余额表[科目名称],A2) -> 0 | M2: =SUMIFS(科目余额表[期末借方],科目余额表[已审报表项目],M$1,科目余额表[科目名称],A2)-SUMIFS(科目余额表[期末贷方],科目余额表[已审报表项目],M$1,科目余额表[科目名称],A2) -> 918044.45 | N2: =SUMIFS(科目余额表[期末贷方],科目余额表[已审报表项目],N$1,科目余额表[科目名称],A2)-SUMIFS(科目余额表[期末借方],科目余额表[已审报表项目],N$1,科目余额表[科目名称],A2) -> 0 | O2: =SUMIFS(科目余额表[期末借方],科目余额表[已审报表项目],O$1,科目余额表[科目名称],A2)-SUMIFS(科目余额表[期末贷方],科目余额表[已审报表项目],O$1,科目余额表[科目名称],A2) -> 0 | P2: =SUMIFS(科目余额表[期末贷方],科目余额表[已审报表项目],P$1,科目余额表[科目名称],A2)-SUMIFS(科目余额表[期末借方],科目余额表[已审报表项目],P$1,科目余额表[科目名称],A2) -> 0 | Q2: =SUMIFS(科目余额表[期末借方],科目余额表[已审报表项目],Q$1,科目余额表[科目名称],A2)-SUMIFS(科目余额表[期末贷方],科目余额表[已审报表项目],Q$1,科目余额表[科目名称],A2) -> 0 | R2: =SUMIFS(科目余额表[期末贷方],科目余额表[已审报表项目],R$1,科目余额表[科目名称],A2)-SUMIFS(科目余额表[期末借方],科目余额表[已审报表项目],R$1,科目余额表[科目名称],A2) -> 0 | S2: =SUMIFS(科目余额表[期末借方],科目余额表[已审报表项目],S$1,科目余额表[科目名称],A2)-SUMIFS(科目余额表[期末贷方],科目余额表[已审报表项目],S$1,科目余额表[科目名称],A2) -> 0 | T2: =SUMIFS(科目余额表[期末贷方],科目余额表[已审报表项目],T$1,科目余额表[科目名称],A2)-SUMIFS(科目余额表[期末借方],科目余额表[已审报表项目],T$1,科目余额表[科目名称],A2) -> 0 | W2: B有限公司 | X2: L有限公司 | Z2: 李四 | AB2: U有限公司 | AE2: 乙
A3: B有限公司 | B3: =IF(COUNTIF(E3:I3,"是")>0,"是","—") -> — | C3: =IF(10-COUNTIF(K3:T3,0)>1,"是","—") -> — | E3: =IF(AND(K3<>0,L3<>0),"是","—") -> — | F3: =IF(AND(M3<>0,N3<>0),"是","—") -> — | G3: =IF(AND(O3<>0,P3<>0),"是","—") -> — | H3: =IF(AND(Q3<>0,R3<>0),"是","—") -> — | I3: =IF(AND(S3<>0,T3<>0),"是","—") -> — | K3: =SUMIFS(科目余额表[期末借方],科目余额表[已审报表项目],K$1,科目余额表[科目名称],A3)-SUMIFS(科目余额表[期末贷方],科目余额表[已审报表项目],K$1,科目余额表[科目名称],A3) -> 0 | L3: =SUMIFS(科目余额表[期末贷方],科目余额表[已审报表项目],L$1,科目余额表[科目名称],A3)-SUMIFS(科目余额表[期末借方],科目余额表[已审报表项目],L$1,科目余额表[科目名称],A3) -> 0 | M3: =SUMIFS(科目余额表[期末借方],科目余额表[已审报表项目],M$1,科目余额表[科目名称],A3)-SUMIFS(科目余额表[期末贷方],科目余额表[已审报表项目],M$1,科目余额表[科目名称],A3) -> 572824.39 | N3: =SUMIFS(科目余额表[期末贷方],科目余额表[已审报表项目],N$1,科目余额表[科目名称],A3)-SUMIFS(科目余额表[期末借方],科目余额表[已审报表项目],N$1,科目余额表[科目名称],A3) -> 0 | O3: =SUMIFS(科目余额表[期末借方],科目余额表[已审报表项目],O$1,科目余额表[科目名称],A3)-SUMIFS(科目余额表[期末贷方],科目余额表[已审报表项目],O$1,科目余额表[科目名称],A3) -> 0 | P3: =SUMIFS(科目余额表[期末贷方],科目余额表[已审报表项目],P$1,科目余额表[科目名称],A3)-SUMIFS(科目余额表[期末借方],科目余额表[已审报表项目],P$1,科目余额表[科目名称],A3) -> 0 | Q3: =SUMIFS(科目余额表[期末借方],科目余额表[已审报表项目],Q$1,科目余额表[科目名称],A3)-SUMIFS(科目余额表[期末贷方],科目余额表[已审报表项目],Q$1,科目余额表[科目名称],A3) -> 0 | R3: =SUMIFS(科目余额表[期末贷方],科目余额表[已审报表项目],R$1,科目余额表[科目名称],A3)-SUMIFS(科目余额表[期末借方],科目余额表[已审报表项目],R$1,科目余额表[科目名称],A3) -> 0 | S3: =SUMIFS(科目余额表[期末借方],科目余额表[已审报表项目],S$1,科目余额表[科目名称],A3)-SUMIFS(科目余额表[期末贷方],科目余额表[已审报表项目],S$1,科目余额表[科目名称],A3) -> 0 | T3: =SUMIFS(科目余额表[期末贷方],科目余额表[已审报表项目],T$1,科目余额表[科目名称],A3)-SUMIFS(科目余额表[期末借方],科目余额表[已审报表项目],T$1,科目余额表[科目名称],A3) -> 0 | W3: C有限公司 | X3: M有限公司 | Z3: 王五 | AB3: M有限公司 | AE3: 丙
A4: C有限公司 | B4: =IF(COUNTIF(E4:I4,"是")>0,"是","—") -> — | C4: =IF(10-COUNTIF(K4:T4,0)>1,"是","—") -> 是 | E4: =IF(AND(K4<>0,L4<>0),"是","—") -> — | F4: =IF(AND(M4<>0,N4<>0),"是","—") -> — | G4: =IF(AND(O4<>0,P4<>0),"是","—") -> — | H4: =IF(AND(Q4<>0,R4<>0),"是","—") -> — | I4: =IF(AND(S4<>0,T4<>0),"是","—") -> — | K4: =SUMIFS(科目余额表[期末借方],科目余额表[已审报表项目],K$1,科目余额表[科目名称],A4)-SUMIFS(科目余额表[期末贷方],科目余额表[已审报表项目],K$1,科目余额表[科目名称],A4) -> 0 | L4: =SUMIFS(科目余额表[期末贷方],科目余额表[已审报表项目],L$1,科目余额表[科目名称],A4)-SUMIFS(科目余额表[期末借方],科目余额表[已审报表项目],L$1,科目余额表[科目名称],A4) -> 0 | M4: =SUMIFS(科目余额表[期末借方],科目余额表[已审报表项目],M$1,科目余额表[科目名称],A4)-SUMIFS(科目余额表[期末贷方],科目余额表[已审报表项目],M$1,科目余额表[科目名称],A4) -> 642499.99 | N4: =SUMIFS(科目余额表[期末贷方],科目余额表[已审报表项目],N$1,科目余额表[科目名称],A4)-SUMIFS(科目余额表[期末借方],科目余额表[已审报表项目],N$1,科目余额表[科目名称],A4) -> 0 | O4: =SUMIFS(科目余额表[期末借方],科目余额表[已审报表项目],O$1,科目余额表[科目名称],A4)-SUMIFS(科目余额表[期末贷方],科目余额表[已审报表项目],O$1,科目余额表[科目名称],A4) -> 0 | P4: =SUMIFS(科目余额表[期末贷方],科目余额表[已审报表项目],P$1,科目余额表[科目名称],A4)-SUMIFS(科目余额表[期末借方],科目余额表[已审报表项目],P$1,科目余额表[科目名称],A4) -> 1126366.6 | Q4: =SUMIFS(科目余额表[期末借方],科目余额表[已审报表项目],Q$1,科目余额表[科目名称],A4)-SUMIFS(科目余额表[期末贷方],科目余额表[已审报表项目],Q$1,科目余额表[科目名称],A4) -> 0 | R4: =SUMIFS(科目余额表[期末贷方],科目余额表[已审报表项目],R$1,科目余额表[科目名称],A4)-SUMIFS(科目余额表[期末借方],科目余额表[已审报表项目],R$1,科目余额表[科目名称],A4) -> 0 | S4: =SUMIFS(科目余额表[期末借方],科目余额表[已审报表项目],S$1,科目余额表[科目名称],A4)-SUMIFS(科目余额表[期末贷方],科目余额表[已审报表项目],S$1,科目余额表[科目名称],A4) -> 0 | T4: =SUMIFS(科目余额表[期末贷方],科目余额表[已审报表项目],T$1,科目余额表[科目名称],A4)-SUMIFS(科目余额表[期末借方],科目余额表[已审报表项目],T$1,科目余额表[科目名称],A4) -> 0 | W4: D有限公司 | X4: N有限公司 | AB4: V有限公司 | AE4: 丁
A5: D有限公司 | B5: =IF(COUNTIF(E5:I5,"是")>0,"是","—") -> — | C5: =IF(10-COUNTIF(K5:T5,0)>1,"是","—") -> — | E5: =IF(AND(K5<>0,L5<>0),"是","—") -> — | F5: =IF(AND(M5<>0,N5<>0),"是","—") -> — | G5: =IF(AND(O5<>0,P5<>0),"是","—") -> — | H5: =IF(AND(Q5<>0,R5<>0),"是","—") -> — | I5: =IF(AND(S5<>0,T5<>0),"是","—") -> — | K5: =SUMIFS(科目余额表[期末借方],科目余额表[已审报表项目],K$1,科目余额表[科目名称],A5)-SUMIFS(科目余额表[期末贷方],科目余额表[已审报表项目],K$1,科目余额表[科目名称],A5) -> 0 | L5: =SUMIFS(科目余额表[期末贷方],科目余额表[已审报表项目],L$1,科目余额表[科目名称],A5)-SUMIFS(科目余额表[期末借方],科目余额表[已审报表项目],L$1,科目余额表[科目名称],A5) -> 0 | M5: =SUMIFS(科目余额表[期末借方],科目余额表[已审报表项目],M$1,科目余额表[科目名称],A5)-SUMIFS(科目余额表[期末贷方],科目余额表[已审报表项目],M$1,科目余额表[科目名称],A5) -> 826988.45 | N5: =SUMIFS(科目余额表[期末贷方],科目余额表[已审报表项目],N$1,科目余额表[科目名称],A5)-SUMIFS(科目余额表[期末借方],科目余额表[已审报表项目],N$1,科目余额表[科目名称],A5) -> 0 | O5: =SUMIFS(科目余额表[期末借方],科目余额表[已审报表项目],O$1,科目余额表[科目名称],A5)-SUMIFS(科目余额表[期末贷方],科目余额表[已审报表项目],O$1,科目余额表[科目名称],A5) -> 0 | P5: =SUMIFS(科目余额表[期末贷方],科目余额表[已审报表项目],P$1,科目余额表[科目名称],A5)-SUMIFS(科目余额表[期末借方],科目余额表[已审报表项目],P$1,科目余额表[科目名称],A5) -> 0 | Q5: =SUMIFS(科目余额表[期末借方],科目余额表[已审报表项目],Q$1,科目余额表[科目名称],A5)-SUMIFS(科目余额表[期末贷方],科目余额表[已审报表项目],Q$1,科目余额表[科目名称],A5) -> 0 | R5: =SUMIFS(科目余额表[期末贷方],科目余额表[已审报表项目],R$1,科目余额表[科目名称],A5)-SUMIFS(科目余额表[期末借方],科目余额表[已审报表项目],R$1,科目余额表[科目名称],A5) -> 0 | S5: =SUMIFS(科目余额表[期末借方],科目余额表[已审报表项目],S$1,科目余额表[科目名称],A5)-SUMIFS(科目余额表[期末贷方],科目余额表[已审报表项目],S$1,科目余额表[科目名称],A5) -> 0 | T5: =SUMIFS(科目余额表[期末贷方],科目余额表[已审报表项目],T$1,科目余额表[科目名称],A5)-SUMIFS(科目余额表[期末借方],科目余额表[已审报表项目],T$1,科目余额表[科目名称],A5) -> 0 | W5: E有限公司 | X5: C有限公司 | AB5: W有限公司 | AE5: 戊
